Workbook
Name Stock: 'CEK CICI'!$A:$N
Name kirim: '2_Barang MJD'!$A$2:$G$78
Name NamedRange1: 'CEK CICI'!$1:$2800
Name BGI: Sheet23!$A:$U
Name hpp: HAJIKUMEDIUM!$A$1:$C$546
Name Stock: 'Current Stock'!$A:$M
Name Tugas: 'TUGAS DAILY'!$A:$G
Name stockKJD: 'Current Stock'!$A$3:$I$2096
Name StockAll: 'Current Stock'!$A$1:$M$2105
Name Penjualan: PENJUALAN!$A$4:$I$11356
Name StockAll: 'CEK CICI'!$A$1:$N$2075
Name stockKJD: 'CEK CICI'!$A$3:$J$2066
Name NamedRange1: 'Current Stock'!$1:$2833

Sheet Current Stock
A1: 4
A2: Kode Barang | B2: Kode Mobil | C2: Tipe Mobil | D2: Part | E2: Merk | F2: Aksesoris | G2: Masuk | H2: Keluar | I2: Stok Akhir | J2: Rak | K2: SO | L2: Alert | M2: Lain - Lain
A3: =CONCATENATE(B3,E3) -> OTH-SEALANTXYG | B3: OTH-SEALANT | C3: Sealant Polyurethane XYG Tube | D3: OTH | E3: XYG | G3: =SUMIFS(X!$F$5:$F$3100,X!$D$5:$D$3100,'Current Stock'!A3) -> 1067 | H3: =SUMIFS(PENJUALAN!$E$4:$E$11000,PENJUALAN!$C$4:$C$11000,'Current Stock'!A3) -> 271 | I3: =G3-H3 -> 796 | L3: 10
A4: =CONCATENATE(B4,E4) -> OTH-PETIKAYU | B4: OTH-PETI | C4: Peti Kayu | D4: OTH | E4: KAYU | G4: =SUMIFS(X!$F$5:$F$2005,X!$D$5:$D$2005,'Current Stock'!A4) -> 32 | H4: =SUMIFS(PENJUALAN!$E$4:$E$11000,PENJUALAN!$C$4:$C$11000,'Current Stock'!A4) -> 211 | I4: =G4-H4 -> -179 | L4: 10
A5: =CONCATENATE(B5,E5) -> LFW-ALTIS18RSXYG | B5: LFW-ALTIS18RS | C5: Toyota Altis 18- E210 12th Gen | D5: LFW | E5: XYG | F5: X/MB/RS/List | G5: =SUMIFS(X!$F$5:$F$2005,X!$D$5:$D$2005,'Current Stock'!A5) -> 1 | H5: =SUMIFS(PENJUALAN!$E$4:$E$11000,PENJUALAN!$C$4:$C$11000,'Current Stock'!A5) -> 1 | I5: =G5-H5 -> 0
A6: =CONCATENATE(B6,E6) -> OTH-SERSK | B6: OTH-SER | C6: 255 Ultra + Actv-100 Application | D6: OTH | E6: SK | G6: =SUMIFS(X!$F$5:$F$2005,X!$D$5:$D$2005,'Current Stock'!A6) -> 0 | H6: =SUMIFS(PENJUALAN!$E$4:$E$11000,PENJUALAN!$C$4:$C$11000,'Current Stock'!A6) -> 0 | I6: =G6-H6 -> 0
A7: =CONCATENATE(B7,E7) -> OTH-SERBY | B7: OTH-SER | C7: 501 Sealant Application | D7: OTH | E7: BY | G7: =SUMIFS(X!$F$5:$F$2005,X!$D$5:$D$2005,'Current Stock'!A7) -> 780 | H7: =SUMIFS(PENJUALAN!$E$4:$E$11000,PENJUALAN!$C$4:$C$11000,'Current Stock'!A7) -> 156 | I7: =G7-H7 -> 624
A8: =CONCATENATE(B8,E8) -> OTH-SERTRANSPORT | B8: OTH-SER | C8: Transport | D8: OTH | E8: TRANSPORT | G8: =SUMIFS(X!$F$5:$F$2005,X!$D$5:$D$2005,'Current Stock'!A8) -> 0 | H8: =SUMIFS(PENJUALAN!$E$4:$E$11000,PENJUALAN!$C$4:$C$11000,'Current Stock'!A8) -> 358 | I8: =G8-H8 -> -358
A9: =CONCATENATE(B9,E9) -> OTH-LIST04TOYDAI | B9: OTH-LIST04 | C9: List Kaca Depan Code 04 | D9: OTH | E9: TOYDAI | G9: =SUMIFS(X!$F$5:$F$2005,X!$D$5:$D$2005,'Current Stock'!A9) -> 60 | H9: =SUMIFS(PENJUALAN!$E$4:$E$11000,PENJUALAN!$C$4:$C$11000,'Current Stock'!A9) -> 58 | I9: =G9-H9 -> 2 | L9: 2
A10: =CONCATENATE(B10,E10) -> OTH-LIST11TOYDAI | B10: OTH-LIST11 | C10: List Kaca Depan Code 11 | D10: OTH | E10: TOYDAI | G10: =SUMIFS(X!$F$5:$F$2005,X!$D$5:$D$2005,'Current Stock'!A10) -> 37 | H10: =SUMIFS(PENJUALAN!$E$4:$E$11000,PENJUALAN!$C$4:$C$11000,'Current Stock'!A10) -> 32 | I10: =G10-H10 -> 5 | L10: 2
A11: =CONCATENATE(B11,E11) -> OTH-LISTINVTOY | B11: OTH-LISTINV | C11: List Kaca Depan INV | D11: OTH | E11: TOY | G11: =SUMIFS(X!$F$5:$F$2005,X!$D$5:$D$2005,'Current Stock'!A11) -> 30 | H11: =SUMIFS(PENJUALAN!$E$4:$E$11000,PENJUALAN!$C$4:$C$11000,'Current Stock'!A11) -> 27 | I11: =G11-H11 -> 3 | L11: 2
A12: =CONCATENATE(B12,E12) -> TRW-DMAX1MSG | B12: TRW-DMAX1 | C12: Isuzu D-Max 02-12 1st Gen | D12: TRW | E12: MSG | G12: =SUMIFS(X!$F$5:$F$2005,X!$D$5:$D$2005,'Current Stock'!A12) -> 2 | H12: =SUMIFS(PENJUALAN!$E$4:$E$11000,PENJUALAN!$C$4:$C$11000,'Current Stock'!A12) -> 2 | I12: =G12-H12 -> 0 | J12: B1T4
A13: =CONCATENATE(B13,E13) -> FDR-DMAX1MSG | B13: FDR-DMAX1 | C13: Isuzu D-Max 02-12 1st Gen | D13: FDR | E13: MSG | G13: =SUMIFS(X!$F$5:$F$2005,X!$D$5:$D$2005,'Current Stock'!A13) -> 1 | H13: =SUMIFS(PENJUALAN!$E$4:$E$11000,PENJUALAN!$C$4:$C$11000,'Current Stock'!A13) -> 1 | I13: =G13-H13 -> 0
A14: =CONCATENATE(B14,E14) -> RDL-DMAX1MSG | B14: RDL-DMAX1 | C14: Isuzu D-Max 02-12 1st Gen | D14: RDL | E14: MSG | G14: =SUMIFS(X!$F$5:$F$2005,X!$D$5:$D$2005,'Current Stock'!A14) -> 2 | H14: =SUMIFS(PENJUALAN!$E$4:$E$11000,PENJUALAN!$C$4:$C$11000,'Current Stock'!A14) -> 1 | I14: =G14-H14 -> 1 | J14: A9T4
A15: =CONCATENATE(B15,E15) -> OTH-RPLXLFW | B15: OTH-RPLX | C15: Pemasangan Kaca Mobil Depan | D15: OTH | E15: LFW | G15: =SUMIFS(X!$F$5:$F$2005,X!$D$5:$D$2005,'Current Stock'!A15) -> 0 | H15: =SUMIFS(PENJUALAN!$E$4:$E$11000,PENJUALAN!$C$4:$C$11000,'Current Stock'!A15) -> 101 | I15: =G15-H15 -> -101 | L15: 100
A16: =CONCATENATE(B16,E16) -> OTH-RPLXTRW | B16: OTH-RPLX | C16: Pemasangan Kaca Mobil Belakang | D16: OTH | E16: TRW | G16: =SUMIFS(X!$F$5:$F$2005,X!$D$5:$D$2005,'Current Stock'!A16) -> 0 | H16: =SUMIFS(PENJUALAN!$E$4:$E$11000,PENJUALAN!$C$4:$C$11000,'Current Stock'!A16) -> 26 | I16: =G16-H16 -> -26 | L16: 100
A17: =CONCATENATE(B17,E17) -> OTH-RPLXSIDE | B17: OTH-RPLX | C17: Pemasangan Kaca Mobil Samping | D17: OTH | E17: SIDE | G17: =SUMIFS(X!$F$5:$F$2005,X!$D$5:$D$2005,'Current Stock'!A17) -> 0 | H17: =SUMIFS(PENJUALAN!$E$4:$E$11000,PENJUALAN!$C$4:$C$11000,'Current Stock'!A17) -> 12 | I17: =G17-H17 -> -12 | L17: 100
A18: =CONCATENATE(B18,E18) -> OTH-SERLMB | B18: OTH-SER | C18: Lembur | D18: OTH | E18: LMB | G18: =SUMIFS(X!$F$5:$F$2005,X!$D$5:$D$2005,'Current Stock'!A18) -> 0 | H18: =SUMIFS(PENJUALAN!$E$4:$E$11000,PENJUALAN!$C$4:$C$11000,'Current Stock'!A18) -> 37 | I18: =G18-H18 -> -37
A19: =CONCATENATE(B19,E19) -> FILM-40STD | B19: FILM-40 | C19: Automotive Film Standard - Black 40% | D19: FILM | E19: STD | G19: =SUMIFS(X!$F$5:$F$2005,X!$D$5:$D$2005,'Current Stock'!A19) -> 0 | H19: =SUMIFS(PENJUALAN!$E$4:$E$11000,PENJUALAN!$C$4:$C$11000,'Current Stock'!A19) -> 17 | I19: =G19-H19 -> -17
A20: =CONCATENATE(B20,E20) -> FILM-60STD | B20: FILM-60 | C20: Automotive Film Standard - Black 60% | D20: FILM | E20: STD | G20: =SUMIFS(X!$F$5:$F$2005,X!$D$5:$D$2005,'Current Stock'!A20) -> 0 | H20: =SUMIFS(PENJUALAN!$E$4:$E$11000,PENJUALAN!$C$4:$C$11000,'Current Stock'!A20) -> 29 | I20: =G20-H20 -> -29
A21: =CONCATENATE(B21,E21) -> FILM-80STD | B21: FILM-80 | C21: Automotive Film Standard - Black 80% | D21: FILM | E21: STD | G21: =SUMIFS(X!$F$5:$F$2005,X!$D$5:$D$2005,'Current Stock'!A21) -> 0 | H21: =SUMIFS(PENJUALAN!$E$4:$E$11000,PENJUALAN!$C$4:$C$11000,'Current Stock'!A21) -> 9 | I21: =G21-H21 -> -9
A22: =CONCATENATE(B22,E22) -> TRW-AVANZA03HAUTO | B22: TRW-AVANZA03H | C22: Toyota Avanza / Xenia 03-11 1st Gen | D22: TRW | E22: AUTO | F22: X/H | G22: =SUMIFS(X!$F$5:$F$2005,X!$D$5:$D$2005,'Current Stock'!A22) -> 0 | H22: =SUMIFS(PENJUALAN!$E$4:$E$11000,PENJUALAN!$C$4:$C$11000,'Current Stock'!A22) -> 0 | I22: =G22-H22 -> 0
A23: =CONCATENATE(B23,E23) -> RDR-CRV12SG | B23: RDR-CRV12 | C23: Honda CR-V 12-16 4th Gen | D23: RDR | E23: SG | G23: =SUMIFS(X!$F$5:$F$2005,X!$D$5:$D$2005,'Current Stock'!A23) -> 0 | H23: =SUMIFS(PENJUALAN!$E$4:$E$11000,PENJUALAN!$C$4:$C$11000,'Current Stock'!A23) -> 0 | I23: =G23-H23 -> 0
A24: =CONCATENATE(B24,E24) -> LFW-ALPHARD08RSPIL | B24: LFW-ALPHARD08RS | C24: Toyota Alphard 08-15 ANH20 2nd Gen | D24: LFW | E24: PIL | F24: X/MB/RS | G24: =SUMIFS(X!$F$5:$F$2005,X!$D$5:$D$2005,'Current Stock'!A24) -> 0 | H24: =SUMIFS(PENJUALAN!$E$4:$E$11000,PENJUALAN!$C$4:$C$11000,'Current Stock'!A24) -> 0 | I24: =G24-H24 -> 0
A25: =CONCATENATE(B25,E25) -> LFW-JAZZ07AGC | B25: LFW-JAZZ07 | C25: Honda Jazz 07-13 2nd Gen (Honda) | D25: LFW | E25: AGC | F25: X/MB/Logo | G25: =SUMIFS(X!$F$5:$F$2005,X!$D$5:$D$2005,'Current Stock'!A25) -> 1 | H25: =SUMIFS(PENJUALAN!$E$4:$E$11000,PENJUALAN!$C$4:$C$11000,'Current Stock'!A25) -> 1 | I25: =G25-H25 -> 0
A26: =CONCATENATE(B26,E26) -> RDR-AVANZA11ASH | B26: RDR-AVANZA11 | C26: Toyota Avanza / Xenia 11-15 2nd Gen | D26: RDR | E26: ASH | G26: =SUMIFS(X!$F$5:$F$2005,X!$D$5:$D$2005,'Current Stock'!A26) -> 10 | H26: =SUMIFS(PENJUALAN!$E$4:$E$11000,PENJUALAN!$C$4:$C$11000,'Current Stock'!A26) -> 9 | I26: =G26-H26 -> 1 | J26: A13T3
A27: =CONCATENATE(B27,E27) -> RDL-AGYA13ASH | B27: RDL-AGYA13 | C27: Toyota Agya/Ayla 13-22 1st Gen | D27: =LEFT(A27,FIND("-",A27) - 1) -> RDL | E27: ASH | G27: =SUMIFS(X!$F$5:$F$2005,X!$D$5:$D$2005,'Current Stock'!A27) -> 5 | H27: =SUMIFS(PENJUALAN!$E$4:$E$11000,PENJUALAN!$C$4:$C$11000,'Current Stock'!A27) -> 4 | I27: =G27-H27 -> 1 | J27: A13T4
A28: =CONCATENATE(B28,E28) -> TRW-AVANZA11ORI | B28: TRW-AVANZA11 | C28: Toyota Avanza / Xenia 11-15 2nd Gen/3rd Gen | D28: TRW | E28: ORI | F28: X/Logo | G28: =SUMIFS(X!$F$5:$F$2005,X!$D$5:$D$2005,'Current Stock'!A28) -> 0 | H28: =SUMIFS(PENJUALAN!$E$4:$E$11000,PENJUALAN!$C$4:$C$11000,'Current Stock'!A28) -> 0 | I28: =G28-H28 -> 0
A29: =CONCATENATE(B29,E29) -> RDL-AVANZA11ORI | B29: RDL-AVANZA11 | C29: Toyota Avanza / Xenia 11-15 2nd Gen/3rd Gen | D29: RDL | E29: ORI | G29: =SUMIFS(X!$F$5:$F$2005,X!$D$5:$D$2005,'Current Stock'!A29) -> 0 | H29: =SUMIFS(PENJUALAN!$E$4:$E$11000,PENJUALAN!$C$4:$C$11000,'Current Stock'!A29) -> 0 | I29: =G29-H29 -> 0
A30: =CONCATENATE(B30,E30) -> RDR-AVANZA11ORI | B30: RDR-AVANZA11 | C30: Toyota Avanza / Xenia 11-15 2nd Gen/3rd Gen | D30: RDR | E30: ORI | G30: =SUMIFS(X!$F$5:$F$2005,X!$D$5:$D$2005,'Current Stock'!A30) -> 0 | H30: =SUMIFS(PENJUALAN!$E$4:$E$11000,PENJUALAN!$C$4:$C$11000,'Current Stock'!A30) -> 0 | I30: =G30-H30 -> 0
A31: =CONCATENATE(B31,E31) -> FDL-AVANZA11ORI | B31: FDL-AVANZA11 | C31: Toyota Avanza / Xenia 11-15 2nd Gen/3rd Gen | D31: FDL | E31: ORI | G31: =SUMIFS(X!$F$5:$F$2005,X!$D$5:$D$2005,'Current Stock'!A31) -> 0 | H31: =SUMIFS(PENJUALAN!$E$4:$E$11000,PENJUALAN!$C$4:$C$11000,'Current Stock'!A31) -> 0 | I31: =G31-H31 -> 0
A32: =CONCATENATE(B32,E32) -> FDR-AVANZA11ORI | B32: FDR-AVANZA11 | C32: Toyota Avanza / Xenia 11-15 2nd Gen/3rd Gen | D32: FDR | E32: ORI | G32: =SUMIFS(X!$F$5:$F$2005,X!$D$5:$D$2005,'Current Stock'!A32) -> 0 | H32: =SUMIFS(PENJUALAN!$E$4:$E$11000,PENJUALAN!$C$4:$C$11000,'Current Stock'!A32) -> 0 | I32: =G32-H32 -> 0
A33: =CONCATENATE(B33,E33) -> LFW-ETIOSASH | B33: LFW-ETIOS | C33: Toyota Etios 10- 1st Gen Sedan | D33: LFW | E33: ASH | F33: X | G33: =SUMIFS(X!$F$5:$F$2005,X!$D$5:$D$2005,'Current Stock'!A33) -> 0 | H33: =SUMIFS(PENJUALAN!$E$4:$E$11000,PENJUALAN!$C$4:$C$11000,'Current Stock'!A33) -> 0 | I33: =G33-H33 -> 0 | L33: 1
A34: =CONCATENATE(B34,E34) -> TRW-XPANDERAGC | B34: TRW-XPANDER | C34: Mitsubishi Xpander 17-21 / Livina 19- 2nd Gen (Mitsubishi) | D34: TRW | E34: AGC | F34: X/Hole | G34: =SUMIFS(X!$F$5:$F$2005,X!$D$5:$D$2005,'Current Stock'!A34) -> 6 | H34: =SUMIFS(PENJUALAN!$E$4:$E$11000,PENJUALAN!$C$4:$C$11000,'Current Stock'!A34) -> 5 | I34: =G34-H34 -> 1 | J34: B10T3
A35: =CONCATENATE(B35,E35) -> SWR-RAIZEORI | B35: SWR-RAIZE | C35: Toyota Raize / Daihatsu Rocky 20- | D35: SWR | E35: ORI | F35: X | G35: =SUMIFS(X!$F$5:$F$2005,X!$D$5:$D$2005,'Current Stock'!A35) -> 0 | H35: =SUMIFS(PENJUALAN!$E$4:$E$11000,PENJUALAN!$C$4:$C$11000,'Current Stock'!A35) -> 0 | I35: =G35-H35 -> 0 | L35: 1
A36: =CONCATENATE(B36,E36) -> TRW-BRV16HONDA | B36: TRW-BRV16 | C36: Honda BR-V 16- Genuine | D36: TRW | E36: HONDA | F36: X/H/Logo | G36: =SUMIFS(X!$F$5:$F$2005,X!$D$5:$D$2005,'Current Stock'!A36) -> 0 | H36: =SUMIFS(PENJUALAN!$E$4:$E$11000,PENJUALAN!$C$4:$C$11000,'Current Stock'!A36) -> 0 | I36: =G36-H36 -> 0 | L36: 1
A37: =CONCATENATE(B37,E37) -> LFW-AUDIB8FY | B37: LFW-AUDIB8 | C37: Audi A4 08-15 B8 | D37: LFW | E37: FY | F37: X/RS/List | G37: =SUMIFS(X!$F$5:$F$2005,X!$D$5:$D$2005,'Current Stock'!A37) -> 0 | H37: =SUMIFS(PENJUALAN!$E$4:$E$11000,PENJUALAN!$C$4:$C$11000,'Current Stock'!A37) -> 0 | I37: =G37-H37 -> 0
A38: =CONCATENATE(B38,E38) -> TRW-AUDIB8FY | B38: TRW-AUDIB8 | C38: Audi A4 08-15 B8 | D38: TRW | E38: FY | F38: X/H/A | G38: =SUMIFS(X!$F$5:$F$2005,X!$D$5:$D$2005,'Current Stock'!A38) -> 0 | H38: =SUMIFS(PENJUALAN!$E$4:$E$11000,PENJUALAN!$C$4:$C$11000,'Current Stock'!A38) -> 0 | I38: =G38-H38 -> 0
A39: =CONCATENATE(B39,E39) -> LFW-AUDIC7FY | B39: LFW-AUDIC7 | C39: Audi A6 11-18 C7 | D39: LFW | E39: FY | F39: X/RS/List | G39: =SUMIFS(X!$F$5:$F$2005,X!$D$5:$D$2005,'Current Stock'!A39) -> 0 | H39: =SUMIFS(PENJUALAN!$E$4:$E$11000,PENJUALAN!$C$4:$C$11000,'Current Stock'!A39) -> 0 | I39: =G39-H39 -> 0
A40: =CONCATENATE(B40,E40) -> TRW-AUDIC7FY | B40: TRW-AUDIC7 | C40: Audi A6 11-18 C7 | D40: TRW | E40: FY | F40: X/H/List | G40: =SUMIFS(X!$F$5:$F$2005,X!$D$5:$D$2005,'Current Stock'!A40) -> 0 | H40: =SUMIFS(PENJUALAN!$E$4:$E$11000,PENJUALAN!$C$4:$C$11000,'Current Stock'!A40) -> 0 | I40: =G40-H40 -> 0
...

Sheet LIST KACA PINDAHAN 
B1: Kode Barang | C1: Rak | D1: Jumlah masuk peti | E1: Peti | F1: SISA DIRAK | G1: Current Stok LIVE | H1: Keterangan
A2: 1 | B2: LFW-DATSUNGOMU | C2: B8T2 | D2: 10 | E2: 1 | F2: 0 | G2: =IFERROR(VLOOKUP(A2,Oktober25,9,FALSE),"") -> #ERROR! | K2: SWR-KAPSUL02LONGASH 3PC | N2: SWR-KAPSUL02LONGASH 4PC
A3: 2 | B3: LFW-JUKEXYG | C3: B9T2 | D3: 0 | E3: 1 | F3: 0 | K3: SFL-HIACEXYG 2PC | N3: SFL-HIACEXYG 2PC
A4: 3 | B4: LFW-CONFEROMU | C4: A8T1 | D4: 1 | E4: 1 | F4: 0 | G4: DIRUKO BARU 1PC | K4: RDL-PICANTO04FY 1PC | N4: RDL-PICANTO04FY 1PC
A5: 4 | B5: LFW-AVANZA11MU | C5: A5T1 | D5: 0 | E5: 2 | F5: 1 | H5: KACA FILM | K5: RDR-PICANTO04FY 1PC | N5: RDR-PICANTO04FY 1PC
A6: 5 | B6: LFW-KAPSUL02XYG | C6: A5T2 | D6: 2 | E6: 2 | F6: 0 | G6: DIRUKO BARU | K6: RDR-FORTUNER05XYG 2PC | N6: RDR-FORTUNER05XYG 2PC
A7: 6 | B7: LFW-FORTUNER15AGC | C7: B3T2 | D7: 0 | E7: 2 | F7: 1 | G7: DIRUKO BARU | K7: RDL-FORTUNER05XYG 2PC | N7: RDL-FORTUNER05XYG 2PC
A8: 7 | B8: LFW-FORTUNER05MSG | C8: A2T2 | D8: 0 | E8: 2 | F8: 1 | G8: DIRUKO BARU | K8: RDR-HILUX05ASH 1PC | N8: RDR-HILUX05ASH 1PC
A9: 9 | B9: LFW-KAPSUL97XYG | C9: A5T2 | D9: 0 | E9: 2 | F9: 0 | G9: DIRUKO BARU | K9: RDR-INNOVA04ASH 1PC | N9: RDR-GRANMAXASH 2PC
A10: 10 | B10: LFW-AVANZA16MU | C10: B2T1 | D10: 0 | E10: 2 | F10: 0 | G10: DIRUKO BARU | K10: RDL-AVANZA21ASH 3PC | N10: RDL-GRANMAXASH 2PC
A11: 11 | B11: LFW-AVANZA03MU | C11: B2T1 | D11: 0 | E11: 2 | F11: 2 | G11: DIRUKO BARU | K11: RDR-AVANZA21ASH 2PC | N11: RDR-INNOVA04ASH 1PC
A12: 12 | B12: LFW-CAMRY02XYG | C12: A1T2 | D12: 2 | E12: 3 | F12: 0 | K12: RDR-CRV02ASH 1PC | N12: RDL-INNOVA04ASH 1PC
A13: 13 | B13: LFW-CAMRY96XYG | C13: A1T2 | D13: 1 | E13: 3 | F13: 0 | K13: RDL-AVANZA11ASH 2PC | N13: RDL-AVANZA111ASH 2PC
A14: 14 | B14: LFW-CAMRY11NORSXYG | C14: A1T2 | D14: 1 | E14: 3 | F14: 0 | K14: RDR-AVANZA11ASH 2PC | N14: RDR-AVANZA11ASH 2PC
A15: 15 | B15: LFW-CAMRY06XYG | C15: A1T2 | D15: 1 | E15: 3 | F15: 0 | K15: RDL-INNOVA04ASH 1PC | N15: RDL-AVANZA21ASH 3PC
A16: 16 | B16: LFW-CAMRY06RSXYG | C16: A1T2 | D16: 0 | E16: 3 | F16: 0 | K16: RDL-HILUX15XYG 1PC | N16: RDR-CRV02ASH 1PC
A17: 17 | B17: LFW-CAMRY11XYG | C17: A1T2 | D17: 1 | E17: 3 | F17: 0 | K17: RDR-HILUX15XYG 0PC | N17: RDL-HILUX15XYG 1PC
A18: 18 | B18: LFW-ALTIS13RSXYG | C18: A1T2 | D18: 1 | E18: 3 | F18: 0 | K18: RDL-AVANZA03ASH 2PC | N18: RDR-HILUX15XYG 1PC
A19: 19 | B19: LFW-RANGER11RSXYG | C19: A3T2 | D19: 2 | E19: 3 | F19: 0 | K19: RDR-AVANZA03ASH 2PC | N19: RDL-AVANZA03ASH 2PC
A20: 20 | B20: LFW-RANGER11MU | C20: A3T2 | D20: 1 | E20: 3 | F20: 0 | K20: RDR-GRANMAXASH 2PC | N20: RDR-AVANZA03ASH 2PC
A21: 21 | B21: LFW-ALTIS00XYG | C21: A1T2 | D21: 1 | E21: 3 | F21: 0 | K21: RDL-GRANMAXASH 2PC | N21: RDR-RUSH17ASH 1PC
A22: 22 | B22: LFW-FIESTAMU | C22: A3T1 | D22: 2 | E22: 4 | F22: 0 | G22: KIRIM 11/11/25 | K22: RDR-RUSH17ASH 1PC | N22: RDL-RUSH17ASH 1PC
A23: 23 | B23: LFW-C26XYG | C23: A1T1 | D23: 0 | E23: 4 | F23: 0 | G23: KIRIM 11/11/25 | K23: RDL-RUSH17ASH 1PC | N23: RDR-LIVINAO07ASH 1PC
A24: 24 | B24: LFW-ALPHARD08RSFR | C24: A1T1 | D24: 1 | E24: 4 | F24: 0 | G24: KIRIM 11/11/25 | K24: RDR-LIVINAO07ASH 1PC | N24: RDL-LIVINA07ASH 1PC
A25: 25 | B25: LFW-ALPHARD08XYG | C25: A1T1 | D25: 1 | E25: 4 | F25: 0 | G25: KIRIM 11/11/25 | K25: RDL-LIVINA07ASH 1PC | N25: RDR-FORTUNER15ASH 1PC
A26: 26 | B26: LFW-VOXY17XYG | C26: A1T2 | D26: 1 | E26: 4 | F26: 0 | G26: KIRIM 11/11/25 | K26: RDR-FORTUNER15ASH 1PC | N26: RDL-TRITON05ASH 1PC
A27: 27 | B27: LFW-VOXY22RSFR | C27: A1T2 | D27: 1 | E27: 4 | F27: 0 | G27: KIRIM 11/11/25 | K27: RDL-TRITON05ASH 1PC | N27: RDR-PAJERO16AGC 1PC
A28: 28 | B28: LFW-W203RS1XYG | C28: A9T2 | D28: 2 | E28: 5 | F28: 0 | G28: KIRIM 11/11/25 | K28: RDR-PAJERO16AGC 1PC | N28: RDL-AGYA13ASH 2PC
A29: 29 | B29: LFW-W204RSFR | C29: A8T2 | D29: 2 | E29: 5 | F29: 0 | G29: KIRIM 11/11/25 | K29: RDL-AGYA13ASH 2PC | N29: RDR-AGYA13ASH 2PC
A30: 30 | B30: LFW-F30XYG | C30: A8T2 | D30: 1 | E30: 5 | F30: 0 | G30: KIRIM 11/11/25 | K30: RDR-AGYA13ASH 2PC | N30: RDL-XPANDERASH 1PC
A31: 31 | B31: LFW-MAZDA214RS1XYG | C31: A4T1 | D31: 0 | E31: 5 | F31: 0 | G31: KIRIM 11/11/25 | K31: RDL-XPANDERASH 1PC | N31: SWR-PANTHER00ASH 2PC
A32: 32 | B32: LFW-MAZDA214RS3XYG | C32: A4T1 | D32: 1 | E32: 5 | F32: 0 | G32: KIRIM 11/11/25 | K32: FDR-ERTIGA12ASH 5PC | N32: FDR-ERTIGA12ASH 5PC
A33: 33 | B33: LFW-CX5GEN1RSXYG | C33: A4T1 | D33: 1 | E33: 5 | F33: 0 | G33: KIRIM 11/11/25 | K33: SWR-PANTHER00ASH 2PC | N33: FDR-L300ASH 5PC
A34: 34 | B34: LFW-CX5GEN1RS2XYG | C34: A4T1 | D34: 1 | E34: 5 | F34: 0 | G34: KIRIM 11/11/25 | N34: FDL-L300ASH 1PC
A35: 35 | B35: LFW-MAZDA209XYG | C35: A4T1 | D35: 1 | E35: 5 | F35: 0 | G35: KIRIM 11/11/25 | N35: RDR-ERTIGA18MU 3PC
A36: 36 | B36: LFW-PAJERO16AGC | C36: A4T2 | D36: 2 | E36: 5 | F36: 2 | G36: KIRIM 11/11/25 | N36: SWL-GRANMAXASH 2PC
A37: 37 | B37: LFW-CIVICESTXYG | C37: B5T2 | D37: 1 | E37: 6 | F37: 0 | G37: DIRUKO BARU | N37: FDR-GRANMAXASH 2PC
A38: 38 | B38: LFW-CIVIC11XYG | C38: B7T1 | D38: 1 | E38: 6 | F38: 0 | G38: DIRUKO BARU | N38: FDL-HRV14PIL 1PC
A39: 39 | B39: LFW-CIVIC05PIL | C39: B7T1 | D39: 2 | E39: 6 | F39: 0 | G39: DIRUKO BARU | N39: RDL-PAJERO16AGC 1PC
A40: 40 | B40: LFW-CIVIC16RSXYG | C40: B7T1 | D40: 1 | E40: 6 | F40: 0 | G40: DIRUKO BARU | N40: FDL-AGYA13ASH 2PC
...

Sheet ASAHIMAS SBY
A1: SWR-KAPSUL02LONGASH 4PC | D1: RDL-AVANZA03ASH 2PC
A2: SFL-HIACEXYG 2PC | D2: RDR-AVANZA03ASH 2PC
A3: RDL-PICANTO04FY 1PC | D3: RDR-GRANMAXASH 2PC
A4: RDR-PICANTO04FY 1PC | D4: RDL-GRANMAXASH 2PC
A5: RDR-FORTUNER05XYG 2PC | D5: RDR-RUSH17ASH 1PC
A6: RDL-FORTUNER05XYG 2PC | D6: RDL-RUSH17ASH 1PC
A7: RDR-HILUX05ASH 1PC | D7: RDR-LIVINAO07ASH 1PC
A8: RDR-INNOVA04ASH 1PC | D8: RDL-LIVINA07ASH 1PC
A9: RDL-AVANZA21ASH 3PC | D9: RDR-FORTUNER15ASH 1PC
A10: RDR-AVANZA21ASH 2PC | D10: RDL-TRITON05ASH 1PC
A11: RDR-CRV02ASH 1PC | D11: RDR-PAJERO16AGC 1PC
A12: RDL-AVANZA11ASH 2PC | D12: RDL-AGYA13ASH 2PC
... A16: RDR-HILUX15XYG 1PC | D16: SWR-PANTHER00ASH 2PC
A21: STOK ASAHIMAS 07/03/2026
A23: Stok asahimas sby | E23: Stok kosong/habis
A25: MERK | B25: JUMLAH | C25: RAK | E25: MERK | F25: JUMLAH | G25: RAK | H25: Order
A26: SWR-KAPSUL02LONGASH | B26: 3 | E26: FDR-LOUHANASH | F26: 0 | H26: ada mu
A27: FDR-JAZZ01ASH | B27: 5 | E27: TRW-KIJANGK125PUASH | F27: 0
A28: FDL-TERIOS06ASH | B28: 5 | E28: FDR-DYNAASH | F28: 0 | H28: 5 | I28: 46094
A29: FDR-ELFNMRASH | B29: 5 | E29: FDL-FE700ASH | F29: 1 | H29: 5 | I29: x
A30: FDR-QUESTERASH | B30: 5 | E30: TRW-AVANZA21ASH | F30: 0 | H30: 5 | I30: x
A31: TRW-KAPSUL02ASH | B31: 5 | E31: FDL-ERTIGA12ASH | F31: 1 | H31: 5 | I31: 46094
A32: FDR-L300ASH | B32: 5 | E32: FDL-GRANMAXASH | F32: 1 | H32: 5 | I32: 46094
A33: SWL-INNOVA04ASH | B33: 5 | E33: FDR-GRANMAXASH | F33: 1 | H33: 5 | I33: 46094
A34: SWR-FORTUNER15ASH | B34: 5 | E34: FDL-VIOS13ASH | F34: 0
A35: FDR-ERTIGA12ASH | B35: 4 | E35: FDR-VIOS13ASH | F35: 0
A36: TRW-AVANZA21HASH | B36: 4 | E36: FDL-FREEDASH | F36: 0
A37: FDL-CARRYFUTURAASH | B37: 5 | E37: FDR-VIOS07ASH | F37: 0
A38: SWR-AVANZA03ASH | B38: 5 | E38: FDR-DATSUNASH | F38: 0
A39: SWL-AVANZA11ASH | B39: 5 | E39: RDR-MOBILIOASH | F39: 0
A40: SWR-AVANZA11ASH | B40: 3 | E40: RDL-CRV02ASH | F40: 0
A41: RDL-AVANZA21ASH | B41: 3 | E41: LFW-BRV22ASH | F41: 0 | H41: 5 | I41: x
A42: FDL-JAZZ01ASH | B42: 5 | E42: RDR-YARIS13ASH | F42: 0 | H42: 5 | I42: x | J42: 3TYR4M-3RDRTA0N
A43: FDR-SIGRA16ASH | B43: 5 | E43: SWR-AVANZA21ASH | F43: 1
E44: - | F44: 0
E45: FDL-RUSH17ASH | F45: 0 | H45: 5 | I45: x
E46: FDR-AVANZA21 | F46: 0 | H46: 5 | I46: x
E47: FDL-DYNAASH | F47: 0 | H47: 5 | I47: x
E48: FDL-ELFNMRASH | F48: 0 | H48: 5 | I48: x
E49: FDL-FORTUNER15ASH | F49: 0 | H49: 5 | I49: x | J49: 3TNF6M-AFDLTA0N
...

Sheet Uang setoran
A1: Tanggal | B1: Nomor Inovice | C1: Total Cash | D1: Total Cash di Setor | E1: Sisa Uang Setor | F1: Ambil cash untuk petty cash | G1: Keterangan | H1: SETOR by LIA
A2: 46070 | B2: B260052 Rp1,350,000 | C2: 1350000 | D2: 1350000 | E2: Rp.70.000 | G2: Sisa tunai Sebelumnya Rp,70.000 | H2: Sudah
A3: 46071 | B3: B260055 Rp.1.000.000 | C3: 1000000 | D3: Rp.4,849,000 + Rp.51.000 (Sisa tunai) = Rp.4.900.000 | E3: 19000 | G3: Sisa tunai Rp.19.000 | H3: Sudah
A4: 46071 | B4: B260056 Rp.3.299.000 | C4: 3299000 | F4: Rp,500.000 | H4: Sudah
A5: 46071 | B5: B260057 Rp.550.000 | C5: 550000 | H5: Sudah
A6: 46073 | B6: B260063 Rp.2.025.000 | C6: Rp.2.025.000 | D6: Rp.2.020.000 | E6: 5000 | G6: Sisa Tunai Rp.24.000 | H6: Belum
A7: 46073 | B7: B260065 Rp.480.00 | C7: 480000 | D7: 480000 | H7: Belum

Sheet PENJUALAN
A1: PENJUALAN
A2: TANGGAL | B2: INV | C2: PRODUK | E2: PC | F2: Penjualan | K2: DAniel SunyotoD | P2: Sales via | Q2: Pembayaran | V2: Input By | W2: KO YAN | X2: Check CICI
C3: KODE | D3: NAMA | F3: Satuan | G3: Jumlah | H3: Diskon | I3: Nett | J3: Jumlah | K3: Nama | L3: No Telp | M3: Email | N3: No Pol | O3: Alamat | Q3: TUNAI | R3: TRANSFER | S3: TOKPED | T3: POTONG | U3: Kembali
A4: 45353 | B4: B240001 | C4: LFW-INNOVA04MSG | D4: =IFERROR(VLOOKUP(C4,Stock,3,FALSE),"") -> Toyota Innova 04-15 1st Gen | E4: 1 | F4: 1625000 | G4: =E4*F4 -> 1625000 | I4: =G4-H4 -> 1625000 | J4: =I4 -> 1625000 | K4: Hari Yulianto | L4: +62 812-3459-2545 | P4: Tokopedia | Q4: 1650000 | V4: CM | X4: done TF AW33
A5: 45356 | B5: C240002 | C5: LFW-JAZZ01MU | D5: =IFERROR(VLOOKUP(C5,Stock,3,FALSE),"") -> Honda Jazz 01-07 1st Gen | E5: 1 | F5: 1698000 | G5: =E5*F5 -> 1698000 | I5: =G5-H5 -> 1698000 | J5: =I5 -> 1698000 | K5: Wahyu | L5: 6282132792913 | P5: Tokopedia | R5: 350000 | S5: 1348000 | T5: 51224 | V5: CM
A6: 45357 | B6: C240003 | C6: LFW-AVANZA16MU | D6: =IFERROR(VLOOKUP(C6,Stock,3,FALSE),"") -> Toyota Avanza / Xenia 15-21 3rd Gen | E6: 3 | F6: 880000 | G6: =E6*F6 -> 2640000 | H6: 264000 | I6: =G6-H6 -> 2376000 | J6: =I6 -> 2376000 | K6: Manuju Jaya (BMJ) | L6: 082199055555 | P6: Tokopedia | R6: 2376000 | V6: CM
A7: 45357 | B7: C240003 | C7: LFW-FJ40MU | D7: =IFERROR(VLOOKUP(C7,Stock,3,FALSE),"") -> Toyota LandCruiser 74- FJ40 / Jeep Hardtop | E7: 1 | F7: 889000 | G7: =E7*F7 -> 889000 | H7: 8900 | I7: =G7-H7 -> 880100 | J7: =I7 -> 880100 | K7: Manuju Jaya | L7: 082199055555 | P7: Tokopedia | R7: 880100 | V7: CM
A8: 45357 | B8: C240003 | C8: OTH-PETIKAYU | D8: =IFERROR(VLOOKUP(C8,Stock,3,FALSE),"") -> Peti Kayu | E8: 1 | F8: 160000 | G8: =E8*F8 -> 160000 | I8: =G8-H8 -> 160000 | J8: =I8 -> 160000 | K8: Manuju Jaya | L8: 082199055555 | P8: Tokopedia | R8: 160000 | V8: CM
A9: 45358 | B9: C240004 | C9: TRW-SIGRA16MU | D9: =IFERROR(VLOOKUP(C9,Stock,3,FALSE),"") -> Toyota Calya / Sigra 16- | E9: 1 | F9: 748000 | G9: =E9*F9 -> 748000 | I9: =G9-H9 -> 748000 | J9: =I9 -> 748000 | K9: Dian Rini | L9: 6282234837411 | N9: - | O9: - | P9: Tokopedia | S9: 748000 | T9: 14960 | V9: CM
A10: 45358 | B10: C240005 | C10: LFW-CX5GEN1RSXYG | D10: =IFERROR(VLOOKUP(C10,Stock,3,FALSE),"") -> Mazda CX-5 .12-14 1st Gen KE Pre - (1 Sensor/ □ ) | E10: 1 | F10: 3666000 | G10: =E10*F10 -> 3666000 | I10: =G10-H10 -> 3666000 | J10: =I10 -> 3666000 | K10: Ricky | L10: +62 811-369-885 | P10: Tokopedia | R10: =J10 -> 3666000 | V10: CM
A11: 45360 | B11: C240006 | C11: TRW-T32XYG | D11: =IFERROR(VLOOKUP(C11,Stock,3,FALSE),"") -> Nissan X-Trail 13- T32 | E11: 1 | F11: 2782000 | G11: =E11*F11 -> 2782000 | I11: =G11-H11 -> 2782000 | J11: =I11 -> 2782000 | K11: Tommy Okan | L11: 6281280000460 | O11: Wonokromo | P11: Tokopedia | R11: 350000 | S11: 2432000 | T11: 92416 | V11: CM
A12: 45360 | B12: C240007 | C12: LFW-JUKEFR | D12: =IFERROR(VLOOKUP(C12,Stock,3,FALSE),"") -> Nissan Juke 11- | E12: 1 | F12: 1782000 | G12: =E12*F12 -> 1782000 | I12: =G12-H12 -> 1782000 | J12: =I12 -> 1782000 | K12: Buddy Tjoanda | L12: 081332154567 | O12: Maluku | P12: Sentra Bekasi | R12: 300000 | V12: CM
A13: 45360 | B13: C240007 | C13: OTH-PETIKAYU | D13: =IFERROR(VLOOKUP(C13,Stock,3,FALSE),"") -> Peti Kayu | E13: 1 | F13: 160000 | G13: =E13*F13 -> 160000 | I13: =G13-H13 -> 160000 | J13: =I13 -> 160000 | K13: Buddy Tjoanda | L13: 081332154567 | O13: Maluku | P13: Sentra Bekasi | V13: CM
A14: 45360 | B14: C240007 | C14: OTH-SERTRANSPORT | D14: =IFERROR(VLOOKUP(C14,Stock,3,FALSE),"") -> Transport | E14: 1 | F14: 250000 | G14: =E14*F14 -> 250000 | I14: =G14-H14 -> 250000 | J14: =I14 -> 250000 | K14: Buddy Tjoanda | L14: 081332154567 | O14: Maluku | P14: Sentra Bekasi | V14: CM
A15: 45363 | B15: C240008 | C15: LFW-CITY96XYG | D15: =IFERROR(VLOOKUP(C15,Stock,3,FALSE),"") -> Honda City 96-02 3rdGen (City Z) | E15: 1 | F15: 1248000 | G15: =E15*F15 -> 1248000 | I15: =G15-H15 -> 1248000 | J15: =I15 -> 1248000 | K15: Budi | L15: +62 813-3140-5595 | O15: Surabaya | P15: Tokopedia | R15: 1248000 | V15: CM
A16: 45363 | B16: C240008 | C16: OTH-SERTRANSPORT | D16: =IFERROR(VLOOKUP(C16,Stock,3,FALSE),"") -> Transport | E16: 1 | F16: 100000 | G16: =E16*F16 -> 100000 | I16: =G16-H16 -> 100000 | J16: =I16 -> 100000 | K16: Budi | L16: +62 813-3140-5595 | O16: Surabaya | P16: Tokopedia | R16: 100000 | V16: CM
A17: 45364 | B17: C240009 | C17: TRW-ALPHARD08BLACKFR | D17: =IFERROR(VLOOKUP(C17,Stock,3,FALSE),"") -> Toyota Alphard 08-15 ANH20 2nd Gen (Hitam) | E17: 1 | F17: 2748000 | G17: =E17*F17 -> 2748000 | I17: =G17-H17 -> 2748000 | J17: =I17 -> 2748000 | K17: Alfian | L17: 6281351878653 | O17: Banjar, KalSel | P17: Tokopedia | S17: 2748000 | T17: 111624 | V17: CM
A18: 45364 | B18: C240009 | C18: OTH-PETIKAYU | D18: =IFERROR(VLOOKUP(C18,Stock,3,FALSE),"") -> Peti Kayu | E18: 1 | F18: 160000 | G18: =E18*F18 -> 160000 | I18: =G18-H18 -> 160000 | J18: =I18 -> 160000 | K18: Alfian | L18: 6281351878653 | O18: Banjar, KalSel | P18: Tokopedia | S18: 160000 | V18: CM
A19: 45364 | B19: C240010 | C19: TRW-ERTIGA12XYG | D19: =IFERROR(VLOOKUP(C19,Stock,3,FALSE),"") -> Suzuki Ertiga 12-18 1st Gen MPV | E19: 1 | F19: 1099000 | G19: =E19*F19 -> 1099000 | I19: =G19-H19 -> 1099000 | J19: =I19 -> 1099000 | K19: Zudi | L19: +62 856-4505-2349 | O19: Lamongan | P19: Bandung | Q19: 1099000 | V19: RA | X19: done tf 33 - 1,100,000
A20: 45364 | B20: C240011 | C20: LFW-INNOVA04XYG | D20: =IFERROR(VLOOKUP(C20,Stock,3,FALSE),"") -> Toyota Innova 04-15 1st Gen | E20: 1 | F20: 1150000 | G20: =E20*F20 -> 1150000 | I20: =G20-H20 -> 1150000 | J20: =I20 -> 1150000 | K20: Indra | L20: 6282228898164 | O20: Surabaya | P20: Tokopedia | R20: 1150000 | V20: RA
A21: 45364 | B21: C240011 | C21: OTH-SERTRANSPORT | D21: =IFERROR(VLOOKUP(C21,Stock,3,FALSE),"") -> Transport | E21: 1 | F21: 100000 | G21: =E21*F21 -> 100000 | I21: =G21-H21 -> 100000 | J21: =I21 -> 100000 | K21: Indra | L21: 6282228898164 | O21: Surabaya | P21: Tokopedia | R21: 100000 | V21: RA
A22: 45364 | B22: C240011 | C22: OTH-PETIKAYU | D22: =IFERROR(VLOOKUP(C22,Stock,3,FALSE),"") -> Peti Kayu | E22: 1 | F22: 160000 | G22: =E22*F22 -> 160000 | I22: =G22-H22 -> 160000 | J22: =I22 -> 160000 | K22: Indra | L22: 6282228898164 | O22: Surabaya | P22: Tokopedia | R22: 160000 | V22: RA
A23: 45364 | B23: C240012 | C23: SWL-ALPHARD08HITAMXYG | D23: =IFERROR(VLOOKUP(C23,Stock,3,FALSE),"") -> Toyota Alphard 08-15 ANH20 2nd Gen (Hitam) | E23: 1 | F23: 3416000 | G23: =E23*F23 -> 3416000 | I23: =G23-H23 -> 3416000 | J23: =I23 -> 3416000 | K23: Daniel Sunyoto | L23: +62 817-399-777 | N23: L 1810 KB | O23: Surabaya | P23: Tokopedia | R23: 100000 | V23: RA | X23: SL-00001
A24: 45365 | B24: C240013 | C24: LFW-PICANTO11PIL | D24: =IFERROR(VLOOKUP(C24,Stock,3,FALSE),"") -> Kia Picanto 11-16 2nd Gen | E24: 1 | F24: 2200000 | G24: =E24*F24 -> 2200000 | I24: =G24-H24 -> 2200000 | J24: =I24 -> 2200000 | L24: +62 895-4025-29766 | O24: Surabaya | P24: Tokopedia | R24: 2200000 | V24: CM
A25: 45366 | B25: C240014 | C25: LFW-T30XYG | D25: =IFERROR(VLOOKUP(C25,Stock,3,FALSE),"") -> Nissan X-Trail 01-07 T30 | E25: 1 | F25: 1971000 | G25: =E25*F25 -> 1971000 | I25: =G25-H25 -> 1971000 | J25: =I25 -> 1971000 | K25: Zainal Arif | L25: +62 813-3678-3983 | N25: L 1884 ABP | O25: Surabaya | P25: Tokopedia | Q25: 2071000 | V25: CM | X25: 19/3/24 terima cash 2071rb
A26: 45366 | B26: C240014 | C26: OTH-SERTRANSPORT | D26: =IFERROR(VLOOKUP(C26,Stock,3,FALSE),"") -> Transport | E26: 1 | F26: 100000 | G26: =E26*F26 -> 100000 | I26: =G26-H26 -> 100000 | J26: =I26 -> 100000 | K26: Zainal Arif | L26: +62 813-3678-3983 | N26: L 1884 ABP | O26: Surabaya | P26: Tokopedia | R26: 100000 | V26: CM
A27: 45366 | B27: C240015 | C27: LFW-HRV14XYG | D27: =IFERROR(VLOOKUP(C27,Stock,3,FALSE),"") -> Honda HR-V 14-21 5D SUV | E27: 1 | F27: 2156000 | G27: =E27*F27 -> 2156000 | I27: =G27-H27 -> 2156000 | J27: =I27 -> 2156000 | K27: Chia | L27: 082139961863 | N27: S 1664 ES | O27: Gubeng, Surabaya | P27: Tokopedia | R27: 400000 | S27: 1756000 | T27: 66728 | V27: CM
A28: 45367 | B28: C240016 | C28: LFW-CITY02MU | D28: =IFERROR(VLOOKUP(C28,Stock,3,FALSE),"") -> Honda City 02-08 4th Gen Idsi GD8 | E28: 1 | F28: 2148000 | G28: =E28*F28 -> 2148000 | I28: =G28-H28 -> 2148000 | J28: =I28 -> 2148000 | K28: Jakasakti | L28: +62 812-3329-7656 | N28: N 1728 EN | O28: Lawang | P28: Tokopedia | Q28: 748000 | R28: 1400000 | V28: CM | X28: 16/3/24 tf 2jt ke aw11, sisa 600rb untuk petty cash
A29: 45367 | B29: C240017 | C29: LFW-SWIFT11MU | D29: =IFERROR(VLOOKUP(C29,Stock,3,FALSE),"") -> Suzuki Swift 11-17 2nd Gen | E29: 1 | F29: 1748000 | G29: =E29*F29 -> 1748000 | I29: =G29-H29 -> 1748000 | J29: =I29 -> 1748000 | K29: Anang | L29: +62 812-3099-1982 | N29: W 1404 QR | P29: Tokopedia | Q29: 1748000 | V29: CM | X29: 16/3/24 tf 2jt ke aw11, sisa 600rb untuk petty cash
A30: 45367 | B30: C240018 | C30: LFW-ELFNMRXYG | D30: =IFERROR(VLOOKUP(C30,Stock,3,FALSE),"") -> Isuzu Elf 17- New NMR NLR | E30: 1 | F30: 1664000 | G30: =E30*F30 -> 1664000 | I30: =G30-H30 -> 1664000 | J30: =I30 -> 1664000 | K30: Agus | L30: +62 857-4236-4861 | N30: S 8115 WM | P30: Ruko | R30: 1664000 | V30: CM
A31: 45367 | B31: C240018 | C31: OTH-SERTRANSPORT | D31: =IFERROR(VLOOKUP(C31,Stock,3,FALSE),"") -> Transport | E31: 1 | F31: 100000 | G31: =E31*F31 -> 100000 | I31: =G31-H31 -> 100000 | J31: =I31 -> 100000 | K31: Agus | L31: +62 857-4236-4861 | N31: S 8115 WM | P31: Ruko | R31: 100000 | V31: CM
A32: 45369 | B32: C240019 | C32: TRW-BRV16XYG | D32: =IFERROR(VLOOKUP(C32,Stock,3,FALSE),"") -> Honda BR-V 16- | E32: 1 | F32: 1259000 | G32: =E32*F32 -> 1259000 | I32: =G32-H32 -> 1259000 | J32: =I32 -> 1259000 | K32: Muhammad Sabirin | L32: 6281349006066 | O32: Banjarbaru | P32: Tokopedia | S32: 1259000 | T32: 55042 | V32: CM
A33: 45369 | B33: C240019 | C33: OTH-PETIKAYU | D33: =IFERROR(VLOOKUP(C33,Stock,3,FALSE),"") -> Peti Kayu | E33: 1 | F33: 160000 | G33: =E33*F33 -> 160000 | I33: =G33-H33 -> 160000 | J33: =I33 -> 160000 | K33: Muhammad Sabirin | L33: 6281349006066 | O33: Banjarbaru | P33: Tokopedia | S33: 160000 | V33: CM
A34: 45370 | B34: C240020 | C34: LFW-VIOS07MU | D34: =IFERROR(VLOOKUP(C34,Stock,3,FALSE),"") -> Toyota Vios 07-13 XP90 2nd Gen | E34: 1 | F34: 1133000 | G34: =E34*F34 -> 1133000 | I34: =G34-H34 -> 1133000 | J34: =I34 -> 1133000 | K34: Mahendra | L34: 6281349006066 | O34: Surabaya | P34: Ruko | Q34: 1133000 | V34: CM | X34: 19/3/24 terima cash 1133rb, masuk petty cash
A35: 45370 | B35: C240020 | C35: TRW-VIOS07XYG | D35: =IFERROR(VLOOKUP(C35,Stock,3,FALSE),"") -> Toyota Vios 07-13 XP90 2nd Gen | E35: 1 | F35: 1354000 | G35: =E35*F35 -> 1354000 | I35: =G35-H35 -> 1354000 | J35: =I35 -> 1354000 | K35: Mahendra | L35: 6281349006066 | O35: Surabaya | P35: Ruko | Q35: 1354000 | V35: CM | X35: 19/3/24 terima cash 1354rb, masuk petty cash
A36: 45371 | B36: C240021 | C36: OTH-SERTRANSPORT | D36: =IFERROR(VLOOKUP(C36,Stock,3,FALSE),"") -> Transport | E36: 1 | F36: 100000 | G36: =E36*F36 -> 100000 | I36: =G36-H36 -> 100000 | J36: =I36 -> 100000 | K36: Agus | L36: +62 857-4236-4861 | N36: S 8115 WM | P36: Ruko | Q36: 100000 | V36: CM | X36: 20/3/24 terima cash 100rb, masuk petty cash
A37: 45371 | B37: C240022 | C37: LFW-TERIOS06MU | D37: =IFERROR(VLOOKUP(C37,Stock,3,FALSE),"") -> Toyota Rush / Terios 06-17 | E37: 1 | F37: 1149000 | G37: =E37*F37 -> 1149000 | I37: =G37-H37 -> 1149000 | J37: =I37 -> 1149000 | K37: cevan missa | L37: 6282146315512 | N37: - | O37: Kupang | P37: Tokopedia | S37: 1149000 | T37: 50862 | V37: CM
A38: 45371 | B38: C240022 | C38: OTH-PETIKAYU | D38: =IFERROR(VLOOKUP(C38,Stock,3,FALSE),"") -> Peti Kayu | E38: 1 | F38: 160000 | G38: =E38*F38 -> 160000 | I38: =G38-H38 -> 160000 | J38: =I38 -> 160000 | K38: cevan missa | L38: 6282146315512 | N38: - | O38: Kupang | P38: Tokopedia | S38: 160000 | V38: CM
A39: 45372 | B39: C240022 | C39: LFW-CITY02MU | D39: =IFERROR(VLOOKUP(C39,Stock,3,FALSE),"") -> Honda City 02-08 4th Gen Idsi GD8 | E39: 1 | F39: 605616 | G39: =E39*F39 -> 605616 | I39: =G39-H39 -> 605616 | J39: =I39 -> 605616 | K39: PECAH | V39: CM
A40: 45372 | B40: C240022 | C40: TRW-YARIS17XYG | D40: =IFERROR(VLOOKUP(C40,Stock,3,FALSE),"") -> Toyota Yaris 18- 3rd Gen (Lampu -) XP151 | E40: 1 | K40: PECAH | V40: CM
...

Sheet INV TTD A4 2
A1: SENTRA AUTOGLASS SURABAYA | J1: Tanggal | L1: 46139
A2: Jl. Bratang Gede No.138, Ngagelrejo, Kec. Wonokromo, Surabaya, Jawa Timur 60245 | J2: Kepada Yth.
A3: (+62) 81288009878 | sentraautoglass.sby@gmail.com | J3: Auto77
J4: +62 856-0608-8887
J5: Surabaya
D7: NOTA PENJUALAN
A9: INV | B9: D260092 | J9: NO POL
A10: No | B10: Kode | C10: =IFERROR(VLOOKUP(B10,Stock,3,FALSE),"") | H10: Qty | J10: Harga Satuan | L10: Jumlah
A11: 1 | B11: OTH-RPLXTRW | C11: =IFERROR(VLOOKUP(B11,Stock,3,FALSE),"") -> Pemasangan Kaca Mobil Belakang | H11: 1 | I11: PC | J11: 450000 | L11: =H11*J11 -> 450000
C12: =IFERROR(VLOOKUP(B12,Stock,3,FALSE),"") | L12: =H12*J12 -> 0
C13: =IFERROR(VLOOKUP(B13,Stock,3,FALSE),"") | L13: =H13*J13 -> 0
C14: =IFERROR(VLOOKUP(B14,Stock,3,FALSE),"") | L14: =H14*J14 -> 0
C15: =IFERROR(VLOOKUP(B15,Stock,3,FALSE),"") | L15: =H15*J15 -> 0
C16: =IFERROR(VLOOKUP(B16,Stock,3,FALSE),"") | L16: =H16*J16 -> 0
B17: BCA 6041794388 an Alvin Wijaya | L17: =H17*J17 -> 0
K18: TOTAL | L18: =SUM(L11:L17) -> 450000
D19: Penerima | F19: Kaca yang sudah dipesan/dipasang tidak dapat dibatalkan/dikembalikan. Tidak ada garansi kaca. | K19: DP
K20: NETTO | L20: =L18-L19 -> 450000
K22: Ket
A23: Trust the Experts, Drive Safer and Clearer | D23: .................... | K23: JASA BONGKAR
A29: SENTRA AUTOGLASS SURABAYA | J29: Tanggal | L29: =L1 -> 46139
A30: =A2 -> Jl. Bratang Gede No.138, Ngagelrejo, Kec. Wonokromo, Surabaya, Jawa Timur 60245 | J30: Kepada Yth.
A31: (+62) 81288009878 | sentraautoglass.sby@gmail.com | J31: =J3 -> Auto77
J32: =J4 -> +62 856-0608-8887
J33: =J5 -> Surabaya
D35: NOTA PENJUALAN
A37: INV | B37: =B9 -> D260092 | J37: NO POL | L37: =L9
A38: No | B38: Kode | C38: Nama Barang | H38: Qty | J38: Harga Satuan | L38: Jumlah
A39: 1 | B39: =B11 -> OTH-RPLXTRW | C39: =IFERROR(VLOOKUP(B39,Stock,3,FALSE),"") -> Pemasangan Kaca Mobil Belakang | H39: =H11 -> 1 | I39: PC | J39: =J11 -> 450000 | L39: =H39*J39 -> 450000
A40: =A12 | B40: =B12 | C40: =IFERROR(VLOOKUP(B40,Stock,3,FALSE),"") | H40: =H12 | I40: =I12 | J40: =J12 | L40: =H40*J40 -> 0
A41: =A13 | B41: =B13 | C41: =IFERROR(VLOOKUP(B41,Stock,3,FALSE),"") | H41: =H13 | I41: =I13 | J41: =J13 | L41: =H41*J41 -> 0
A42: =A14 | B42: =B14 | C42: =IFERROR(VLOOKUP(B42,Stock,3,FALSE),"") | H42: =H14 | I42: =I14 | J42: =J14 | L42: =H42*J42 -> 0
A43: =A15 | B43: =B15 | C43: =IFERROR(VLOOKUP(B43,Stock,3,FALSE),"") | H43: =H15 | I43: =I15 | J43: =J15 | L43: =H43*J43 -> 0
L44: =H44*J44 -> 0
A45: =A17 | B45: =B17 -> BCA 6041794388 an Alvin Wijaya | I45: =I17 | J45: =J17 | L45: =L17 -> 0
K46: TOTAL | L46: =L18 -> 450000
D47: Penerima | F47: Kaca yang sudah dipesan/dipasang tidak dapat dibatalkan/dikembalikan. Tidak ada garansi kaca. | K47: =K19 -> DP | L47: =L19
K48: NETTO | L48: =L20 -> 450000
K50: Ket
A51: Trust the Experts, Drive Safer and Clearer | D51: .................... | K51: =K23 -> JASA BONGKAR
...

Sheet INV TTD A4 3
A1: SENTRA AUTOGLASS SURABAYA | J1: Tanggal | L1: 46139
A2: Jl. Bratang Gede No.138, Ngagelrejo, Kec. Wonokromo, Surabaya, Jawa Timur 60245 | J2: Kepada Yth.
A3: (+62) 81288009878 | sentraautoglass.sby@gmail.com | J3: Bpk Piter candra
J4: +62 818-542-003
J5: Surabaya
D7: NOTA PENJUALAN
A9: INV | B9: D260092 | J9: NO POL
A10: No | B10: Kode | C10: Nama Barang | H10: Qty | J10: Harga Satuan | L10: Jumlah
A11: 1 | B11: LFW-TERRA18RSXYG | C11: =IFERROR(VLOOKUP(B11,Stock,3,FALSE),"") -> Nissan Terra 18- | H11: 1 | I11: PC | J11: 3000000 | L11: =H11*J11 -> 3000000
A12: 2 | B12: OTH-PETIKAYU | C12: =IFERROR(VLOOKUP(B12,Stock,3,FALSE),"") -> Peti Kayu | H12: 1 | I12: X | J12: 200000 | L12: =H12*J12 -> 200000
C13: =IFERROR(VLOOKUP(B13,Stock,3,FALSE),"") | L13: =H13*J13 -> 0
C14: =IFERROR(VLOOKUP(B14,Stock,3,FALSE),"") | L14: =H14*J14 -> 0
C15: =IFERROR(VLOOKUP(B15,Stock,3,FALSE),"") | L15: =H15*J15 -> 0
C16: =IFERROR(VLOOKUP(B16,Stock,3,FALSE),"") | L16: =H16*J16 -> 0
C17: =IFERROR(VLOOKUP(B17,Stock,3,FALSE),"")
B18: BCA 6041794388 an Alvin Wijaya | L18: =H18*J18 -> 0
K19: TOTAL | L19: =SUM(L11:L18) -> 3200000
D20: Penerima | F20: Kaca yang sudah dipesan/dipasang tidak dapat dibatalkan/dikembalikan. Tidak ada garansi kaca. | K20: DP | L20: 1600000
K21: NETTO | L21: =L19-L20 -> 1600000
K23: Ket
A24: Trust the Experts, Drive Safer and Clearer | D24: .................... | K24: EXCLUDE BIAYA CARGO
A30: SENTRA AUTOGLASS SURABAYA | J30: Tanggal | L30: =L1 -> 46139
A31: =A2 -> Jl. Bratang Gede No.138, Ngagelrejo, Kec. Wonokromo, Surabaya, Jawa Timur 60245 | J31: Kepada Yth.
A32: (+62) 81288009878 | sentraautoglass.sby@gmail.com | J32: =J3 -> Bpk Piter candra
J33: =J4 -> +62 818-542-003
J34: =J5 -> Surabaya
J35: =J6
D36: NOTA PENJUALAN
A38: INV | B38: =B9 -> D260092 | J38: NO POL | L38: =L9
A39: No | B39: Kode | C39: Nama Barang | H39: Qty | J39: Harga Satuan | L39: Jumlah
A40: =A11 -> 1 | B40: =B11 -> LFW-TERRA18RSXYG | C40: =IFERROR(VLOOKUP(B40,Stock,3,FALSE),"") -> Nissan Terra 18- | H40: =H11 -> 1 | I40: PC | J40: =J11 -> 3000000 | L40: =H40*J40 -> 3000000
A41: =A12 -> 2 | B41: =B12 -> OTH-PETIKAYU | C41: =IFERROR(VLOOKUP(B41,Stock,3,FALSE),"") -> Peti Kayu | H41: =H12 -> 1 | I41: =I12 -> X | J41: =J12 -> 200000 | L41: =H41*J41 -> 200000
A42: =A13 | B42: =B13 | C42: =IFERROR(VLOOKUP(B42,Stock,3,FALSE),"") | H42: =H13 | I42: =I13 | J42: =J13 | L42: =H42*J42 -> 0
A43: =A14 | B43: =B14 | C43: =IFERROR(VLOOKUP(B43,Stock,3,FALSE),"") | H43: =H14 | I43: =I14 | J43: =J14 | L43: =H43*J43 -> 0
A44: =A15 | B44: =B15 | C44: =IFERROR(VLOOKUP(B44,Stock,3,FALSE),"") | H44: =H15 | I44: =I15 | J44: =J15 | L44: =H44*J44 -> 0
B45: =B16 | L45: =H45*J45 -> 0
A46: =A18 | B46: =B18 -> BCA 6041794388 an Alvin Wijaya | I46: =I18 | J46: =J18 | L46: =L18 -> 0
K47: TOTAL | L47: =L19 -> 3200000
D48: Penerima | F48: Kaca yang sudah dipesan/dipasang tidak dapat dibatalkan/dikembalikan. Tidak ada garansi kaca. | K48: =K20 -> DP | L48: =L20 -> 1600000
K49: NETTO | L49: =L21 -> 1600000
...

Sheet  INV TTD A4 1 PDF
B1: SENTRA AUTOGLASS SURABAYA | K1: Tanggal | M1: 46139
B2: Jl. Bratang Gede No.138, Ngagelrejo, Kec. Wonokromo, Surabaya, Jawa Timur 60245 | K2: Kepada Yth.
B3: (+62) 81288009878 | sentraautoglass.sby@gmail.com | K3: P. David
K4: +62 857-3050-8510
K5: Surabaya
E7: NOTA PENJUALAN
B9: INV | C9: D260094 | K9: NO POL
B10: No | C10: Kode | D10: Nama Barang | I10: Qty | K10: Harga Satuan | M10: Jumlah
B11: 1 | C11: LFW-T30MU | D11: =IFERROR(VLOOKUP(C11,Stock,3,FALSE),"") -> Nissan X-Trail 01-07 T30 | I11: 1 | J11: PC | K11: 1521000 | M11: =I11*K11 -> 1521000
B12: 2 | C12: OTH-PETIKAYU | D12: =IFERROR(VLOOKUP(C12,Stock,3,FALSE),"") -> Peti Kayu | I12: 1 | J12: X | K12: 200000 | M12: =I12*K12 -> 200000
D13: =IFERROR(VLOOKUP(C13,Stock,3,FALSE),"") | M13: =I13*K13 -> 0
D14: =IFERROR(VLOOKUP(C14,Stock,3,FALSE),"") | M14: =I14*K14 -> 0
D15: =IFERROR(VLOOKUP(C15,Stock,3,FALSE),"") | M15: =I15*K15 -> 0
C16: BCA 6041794388 an Alvin Wijaya | M16: =I16*K16 -> 0
L17: TOTAL | M17: =SUM(M11:M16) -> 1721000
E18: Penerima | G18: Kaca yang sudah dipesan/dipasang tidak dapat dibatalkan/dikembalikan. Tidak ada garansi kaca. | L18: DP
L19: NETTO | M19: =M17-M18 -> 1721000
L21: Ket
B22: Trust the Experts, Drive Safer and Clearer | E22: .................... | L22: LUNAS

Sheet INV VIRTUAL
A1: SENTRA AUTOGLASS SURABAYA | J1: Tanggal | L1: 46133
A2: Jl. Bratang Gede No.138, Ngagelrejo, Kec. Wonokromo, Surabaya, Jawa Timur 60245 | J2: Kepada Yth.
A3: (+62) 81288009878 | sentraautoglass.sby@gmail.com | J3: KARMAWAN BAJAWA(Amel)
J4: Surabaya
D7: NOTA PENJUALAN
A9: INV | B9: D260078 | J9: NO POL
A10: No | B10: Kode | C10: Nama Barang | H10: Qty | J10: Harga Satuan | L10: Jumlah
A11: 1 | B11: LFW-CAPTIVAXYG | C11: =IFERROR(VLOOKUP(B11,Stock,3,FALSE),"") -> Chevrolet Captiva 06-18 1st gen C100 | H11: 1 | I11: PC | J11: 1802000 | L11: =H11*J11 -> 1802000
C12: =IFERROR(VLOOKUP(B12,Stock,3,FALSE),"") | L12: =H12*J12 -> 0
C13: =IFERROR(VLOOKUP(B13,Stock,3,FALSE),"") | L13: =H13*J13 -> 0
C14: =IFERROR(VLOOKUP(B14,Stock,3,FALSE),"") | L14: =H14*J14 -> 0
L15: =H15*J15 -> 0
K16: TOTAL | L16: =SUM(L11:L15) -> 1802000
F17: Kaca yang sudah dipesan/dipasang tidak dapat dibatalkan/dikembalikan. Tidak ada garansi kaca. | K17: DP
K18: NETTO | L18: =L16-L17 -> 1802000
K20: Ket
A21: Trust the Experts, Drive Safer and Clearer | K21: KIRIM

Sheet SURAT JALAN
A1: SENTRA AUTOGLASS SURABAYA | I1: Tanggal | L1: 46128
A2: Jl. Bratang Gede No.138, Ngagelrejo, Kec. Wonokromo, Surabaya, Jawa Timur | I2: Kepada Yth.
A3: (+62) 81288009878 | sentraautoglass.sby@gmail.com | I3: Expedisi Karya Bersama(CV Abirama)
I4: Surabaya
D9: SURAT JALAN
A10: NO | B10: D260056
A11: No | B11: Kode | C11: Nama Barang | H11: Keterangan | L11: QTY
A12: 1 | B12: LFW-CARRY19XYG | C12: =IFERROR(VLOOKUP(B12,Stock,3,FALSE),"") -> Suzuki Carry New 19- | L12: 1
C14: =IFERROR(VLOOKUP(B14,Stock,3,FALSE),"")
C15: =IFERROR(VLOOKUP(B15,Stock,3,FALSE),"")
C16: =IFERROR(VLOOKUP(B16,Stock,3,FALSE),"")
K17: Total
E18: Penerima | J18: Kaca yang sudah dipesan tidak dapat dibatalkan/dikembalikan.
B20: Trust the Experts, Drive Safer and Clearer
E21: .................... | K21: KET :
K22: KIRIM

Sheet PO
A1: Order | H1: Terima | K1: DONE
A2: Tanggal | B2: Supplier | C2: Kode | D2: Nama Barang | E2: PC | G2: Keterangan | H2: Tanggal | I2: PC | J2: Keterangan/Nota no
A3: 45784 | B3: BGI | C3: LFW-MAZDA209XYG | D3: =IFERROR(VLOOKUP(C3,Stock,3,FALSE),"") -> Mazda 2 09-14 3rd Gen | E3: 2 | G3: READY SBY | H3: 45785 | I3: 2 | K3: TRUE
A4: 45784 | B4: BGI | C4: LFW-YARIS05MU | D4: =IFERROR(VLOOKUP(C4,Stock,3,FALSE),"") -> Toyota Yaris 05-13 XP90 1st Gen | E4: 2 | G4: READY SBY | H4: 45785 | I4: 2 | K4: TRUE
A5: 45784 | B5: BGI | C5: TRW-JAZZ07XYG | D5: =IFERROR(VLOOKUP(C5,Stock,3,FALSE),"") -> Honda Jazz 07-13 2nd Gen | E5: 2 | G5: READY JKT | K5: FALSE
A6: 45775 | B6: BGI | C6: LFW-CONFEROXYG | D6: =IFERROR(VLOOKUP(C6,Stock,3,FALSE),"") -> Wuling Confero (Tanpa Spionnya) | E6: 2 | G6: READY JKT | K6: FALSE
A7: 45775 | B7: BGI | C7: TRW-RUSH17XYG | D7: =IFERROR(VLOOKUP(C7,Stock,3,FALSE),"") -> Toyota Rush / Terios 18- | E7: 3 | G7: READY JKT | K7: FALSE
A8: 45775 | B8: BGI | C8: TRW-AVANZA03XYG | D8: =IFERROR(VLOOKUP(C8,Stock,3,FALSE),"") -> Toyota Avanza / Xenia 03-11 1st Gen | E8: 5 | G8: READY JKT | K8: FALSE
A9: 45775 | B9: BGI | C9: TRW-YARIS13XYG | D9: =IFERROR(VLOOKUP(C9,Stock,3,FALSE),"") -> Toyota Yaris 13- 2nd Gen (Lampu C) XP150 | E9: 1 | G9: READY JKT | K9: FALSE
A10: 45775 | B10: BGI | C10: TRW-JAZZ01XYG | D10: =IFERROR(VLOOKUP(C10,Stock,3,FALSE),"") -> Honda Jazz 01-07 1st Gen | E10: 1 | G10: READY JKT | K10: FALSE
A11: 45775 | B11: BGI | C11: TRW-BRIO18XYG | D11: =IFERROR(VLOOKUP(C11,Stock,3,FALSE),"") -> Honda Brio 18- | E11: 2 | G11: READY JKT | K11: FALSE
A12: 45775 | B12: BGI | C12: TRW-LIVINA07XYG | D12: =IFERROR(VLOOKUP(C12,Stock,3,FALSE),"") -> Nissan Livina 07-12 L10 (Tanpa Lubang) | E12: 3 | G12: READY JKT | K12: FALSE
A13: 45785 | B13: BGI | C13: LFW-ALTIS06RSXYG | D13: =IFERROR(VLOOKUP(C13,Stock,3,FALSE),"") -> Toyota Altis 06-13 E140 10th Gen | E13: 1 | G13: READY JKT | K13: FALSE
A14: 45786 | B14: BGI | C14: LFW-VIOS13MU | D14: =IFERROR(VLOOKUP(C14,Stock,3,FALSE),"") -> Toyota Yaris 13- 2nd Gen / Vios 14- 3rd Gen | E14: 3 | G14: READY SBY | K14: FALSE
C15: LFW-CX5GEN1RS3XYG | D15: =IFERROR(VLOOKUP(C15,Stock,3,FALSE),"") -> Mazda CX-5 .14-17 1st Gen KE Facelift - (3 Sensor/ /\8 ) | E15: 1 | K15: FALSE
C16: LFW-E84XYG | D16: =IFERROR(VLOOKUP(C16,Stock,3,FALSE),"") -> BMW X1 Series 09-14 E84 (1 Sensor / [] ) | E16: 1 | K16: FALSE
C17: TRW-SIRION1XYG | D17: =IFERROR(VLOOKUP(C17,Stock,3,FALSE),"") -> Daihatsu Sirion 04-10 1st Gen | E17: 1 | K17: FALSE
C18: LFW-ECOSPORTXYG | D18: =IFERROR(VLOOKUP(C18,Stock,3,FALSE),"") -> Ford EcoSport 13- B515 | E18: 1 | K18: FALSE
C19: LFW-CRV17XYG | D19: =IFERROR(VLOOKUP(C19,Stock,3,FALSE),"") -> Honda CR-V 17- 5th Gen | E19: 1 | K19: FALSE
C20: LFW-HRV14XYG | D20: =IFERROR(VLOOKUP(C20,Stock,3,FALSE),"") -> Honda HR-V 14-21 5D SUV | E20: 1 | K20: FALSE
C21: TRW-JAZZ07XYG | D21: =IFERROR(VLOOKUP(C21,Stock,3,FALSE),"") -> Honda Jazz 07-13 2nd Gen | E21: 2 | K21: FALSE
C22: LFW-JAZZ13XYG | D22: =IFERROR(VLOOKUP(C22,Stock,3,FALSE),"") -> Honda Jazz 13- 3rd Gen | E22: 1 | K22: FALSE
C23: LFW-GAVEGAXYG | D23: =IFERROR(VLOOKUP(C23,Stock,3,FALSE),"") -> Hyundai Grand Avega 11-16 RB | E23: 1 | K23: FALSE
C24: LFW-DMAX2XYG | D24: =IFERROR(VLOOKUP(C24,Stock,3,FALSE),"") -> Isuzu D-Max 12-19 2nd Gen | E24: 1 | K24: FALSE
C25: LFW-RIO11XYG | D25: =IFERROR(VLOOKUP(C25,Stock,3,FALSE),"") -> Kia Rio 11-17 UB Hatchback | E25: 1 | K25: FALSE
C26: LFW-SPORTAGE10XYG | D26: =IFERROR(VLOOKUP(C26,Stock,3,FALSE),"") -> Kia Sportage 10-15 SL | E26: 1 | K26: FALSE
... C58: LFW-SPARK10XYG | D58: =IFERROR(VLOOKUP(C58,Stock,3,FALSE),"") -> Chevrolet Spark 10-15 M300 3rd Gen (1200cc) | E58: 1 | K58: FALSE
A59: 45796 | B59: PMK | C59: LFW-FORTUNER15AGC | D59: =IFERROR(VLOOKUP(C59,Stock,3,FALSE),"") -> Toyota Fortuner 15- 2nd Gen (Toyota) | E59: 3 | G59: PO 3-4 HARI | H59: 45798 | I59: 2 | J59: 3pc , lunas | K59: TRUE
A60: 45804 | B60: BGI | C60: LFW-FE700MU | D60: =IFERROR(VLOOKUP(C60,Stock,3,FALSE),"") -> Mitsubishi Canter FE700 01- (PS110,125) | E60: 2 | K60: FALSE
D61: =IFERROR(VLOOKUP(C61,Stock,3,FALSE),"") | K61: FALSE
D62: =IFERROR(VLOOKUP(C62,Stock,3,FALSE),"") | K62: FALSE
D63: =IFERROR(VLOOKUP(C63,Stock,3,FALSE),"") | K63: FALSE
D64: =IFERROR(VLOOKUP(C64,Stock,3,FALSE),"") | K64: FALSE
K65: FALSE
K66: FALSE
K67: FALSE
K68: FALSE
K69: FALSE
K70: FALSE
K71: FALSE
...

Sheet  INV POLOS
J1: Tanggal | L1: 46134
J2: Kepada Yth.
J3: P. Tasman
J4: +62 813-3530-5670
J5: Sidoarjo
D7: NOTA PENJUALAN
A9: INV | B9: D260079 | J9: NO POL
A10: No | B10: Kode | C10: Nama Barang | H10: Qty | J10: Harga Satuan | L10: Jumlah
A11: 1 | B11: LFW-CAMRY06RSXYG | C11: =IFERROR(VLOOKUP(B11,Stock,3,FALSE),"") -> Toyota Camry 06-11 XV40 4th Gen | H11: 1 | I11: PC | J11: 3223000 | L11: =H11*J11 -> 3223000
C12: =IFERROR(VLOOKUP(B12,Stock,3,FALSE),"") | L12: =H12*J12 -> 0
C13: =IFERROR(VLOOKUP(B13,Stock,3,FALSE),"") | L13: =H13*J13 -> 0
C14: =IFERROR(VLOOKUP(B14,Stock,3,FALSE),"") | L14: =H14*J14 -> 0
L15: =H15*J15 -> 0
K17: TOTAL | L17: =SUM(L11:L16) -> 3223000
C18: Penerima | F18: Kaca yang sudah dipesan/dipasang tidak dapat dibatalkan/dikembalikan. Tidak ada garansi kaca. | K18: DEPOSIT
K19: NETTO | L19: =L17-L18 -> 3223000
C21: ................... | K21: Ket

Sheet INV TTD A4 KF
A1: SENTRA AUTOGLASS SURABAYA | J1: Tanggal | L1: 45740
A2: Jalan Simo Jawar No. 108, Simomulyo Baru, Sukomanunggal, Surabaya | J2: Kepada Yth.
A3: (+62) 81288009878 | sentraautoglass.sby@gmail.com | J3: P. Deny
J4: +62 877-6251-4735
J5: Surabaya
D7: NOTA PENJUALAN
A9: INV | B9: C250081 | J9: NO POL
A10: No | B10: Kode | C10: Nama Barang | H10: Qty | J10: Harga Satuan | L10: Jumlah
A11: 1 | B11: LFW-AVANZA16MU | C11: =IFERROR(VLOOKUP(B11,Stock,3,FALSE),"") -> Toyota Avanza / Xenia 15-21 3rd Gen | H11: 1 | I11: PC | J11: 1050000 | L11: =H11*J11 -> 1050000
A12: 2 | B12: FILM-40STD | C12: =IFERROR(VLOOKUP(B12,Stock,3,FALSE),"") -> Automotive Film Standard - Black 40% | H12: 1 | I12: X | J12: 350000 | L12: =H12*J12 -> 350000
C13: =IFERROR(VLOOKUP(B13,Stock,3,FALSE),"") | L13: =H13*J13 -> 0
C14: =IFERROR(VLOOKUP(B14,Stock,3,FALSE),"") | L14: =H14*J14 -> 0
C15: =IFERROR(VLOOKUP(B15,Stock,3,FALSE),"") | L15: =H15*J15 -> 0
L16: =H16*J16 -> 0
B17: BCA 6041794388 an Alvin Wijaya | L17: =H17*J17 -> 0
K18: TOTAL | L18: =SUM(L11:L17) -> 1400000
D19: Penerima | F19: Kaca yang sudah dipesan/dipasang tidak dapat dibatalkan/dikembalikan. | K19: DISKON | L19: 150000
K20: NETTO | L20: =L18-L19 -> 1250000
K22: Ket
A23: Trust the Experts, Drive Safer and Clearer | D23: ....................
A31: SENTRA AUTOGLASS SURABAYA | J31: Tanggal | L31: =L1 -> 45740
A32: Jalan Simo Jawar No. 108, Simomulyo Baru, Sukomanunggal, Surabaya | J32: Kepada Yth.
A33: (+62) 81288009878 | sentraautoglass.sby@gmail.com | J33: =J3 -> P. Deny
J34: =J4 -> +62 877-6251-4735
J35: =J5 -> Surabaya
D37: NOTA PENJUALAN
A39: INV | B39: =B9 -> C250081 | J39: NO POL | L39: =L9
A40: No | B40: Kode | C40: Nama Barang | H40: Qty | J40: Harga Satuan | L40: Jumlah
A41: 1 | B41: =B11 -> LFW-AVANZA16MU | C41: =C11 -> Toyota Avanza / Xenia 15-21 3rd Gen | H41: =H11 -> 1 | I41: =I11 -> PC | J41: =J11 -> 1050000 | L41: =H41*J41 -> 1050000
A42: =A12 -> 2 | B42: =B12 -> FILM-40STD | C42: =IFERROR(VLOOKUP(B42,Stock,3,FALSE),"") -> Automotive Film Standard - Black 40% | H42: =H12 -> 1 | I42: =I12 -> X | J42: =J12 -> 350000 | L42: =L12 -> 350000
A43: =A13 | B43: =B13 | C43: =IFERROR(VLOOKUP(B43,Stock,3,FALSE),"") | H43: =H13 | I43: =I13 | J43: =J13 | L43: =L13 -> 0
A44: =A14 | B44: =B14 | C44: =IFERROR(VLOOKUP(B44,Stock,3,FALSE),"") | H44: =H14 | I44: =I14 | J44: =J14 | L44: =L14 -> 0
A45: =A15 | B45: =B15 | C45: =IFERROR(VLOOKUP(B45,Stock,3,FALSE),"") | H45: =H15 | I45: =I15 | J45: =J15 | L45: =L15 -> 0
A46: =A16 | B46: =B16 | C46: =IFERROR(VLOOKUP(B46,Stock,3,FALSE),"") | H46: =H16 | I46: =I16 | J46: =J16 | L46: =L16 -> 0
A47: =A17 | B47: =B17 -> BCA 6041794388 an Alvin Wijaya | H47: =H17 | I47: =I17 | J47: =J17 | L47: =L17 -> 0
K48: TOTAL | L48: =L18 -> 1400000
D49: Penerima | F49: Kaca yang sudah dipesan/dipasang tidak dapat dibatalkan/dikembalikan. | K49: DISKON | L49: =L19 -> 150000
K50: NETTO | L50: =L20 -> 1250000
K52: Ket
A53: Trust the Experts, Drive Safer and Clearer | D53: .................... | K53: =K23

Sheet CEK CICI
A2: Kode Barang | B2: Kode Mobil | C2: Tipe Mobil | D2: Part | E2: Merk | F2: Aksesoris | G2: ORDER | H2: Masuk | I2: Keluar | J2: Stok Akhir | K2: Rak | L2: SO | M2: Alert | N2: Lain - Lain
A3: =CONCATENATE(B3,E3) -> OTH-SEALANTXYG | B3: OTH-SEALANT | C3: Sealant Polyurethane XYG Tube | D3: OTH | E3: XYG | H3: =SUMIFS(X!$F$5:$F$2005,X!$D$5:$D$2005,'CEK CICI'!A3) -> 1067 | I3: =SUMIFS(PENJUALAN!$E$4:$E$4288,PENJUALAN!$C$4:$C$4288,'CEK CICI'!A3) -> 271 | J3: =H3-I3 -> 796 | M3: 10
A4: =CONCATENATE(B4,E4) -> OTH-PETIKAYU | B4: OTH-PETI | C4: Peti Kayu | D4: OTH | E4: KAYU | H4: =SUMIFS(X!$F$5:$F$2005,X!$D$5:$D$2005,'CEK CICI'!A4) -> 32 | I4: =SUMIFS(PENJUALAN!$E$4:$E$4288,PENJUALAN!$C$4:$C$4288,'CEK CICI'!A4) -> 211 | J4: =H4-I4 -> -179 | M4: 10
A5: =CONCATENATE(B5,E5) -> OTH-SERTR | B5: OTH-SER | C5: 9092 Sealant Application | D5: OTH | E5: TR | H5: =SUMIFS(X!$F$5:$F$2005,X!$D$5:$D$2005,'CEK CICI'!A5) -> 20 | I5: =SUMIFS(PENJUALAN!$E$4:$E$4288,PENJUALAN!$C$4:$C$4288,'CEK CICI'!A5) -> 18 | J5: =H5-I5 -> 2
A6: =CONCATENATE(B6,E6) -> OTH-SERBY | B6: OTH-SER | C6: 501 Sealant Application | D6: OTH | E6: BY | H6: =SUMIFS(X!$F$5:$F$2005,X!$D$5:$D$2005,'CEK CICI'!A6) -> 780 | I6: =SUMIFS(PENJUALAN!$E$4:$E$4288,PENJUALAN!$C$4:$C$4288,'CEK CICI'!A6) -> 156 | J6: =H6-I6 -> 624
A7: =CONCATENATE(B7,E7) -> OTH-SERTRANSPORT | B7: OTH-SER | C7: Transport | D7: OTH | E7: TRANSPORT | H7: =SUMIFS(X!$F$5:$F$2005,X!$D$5:$D$2005,'CEK CICI'!A7) -> 0 | I7: =SUMIFS(PENJUALAN!$E$4:$E$4288,PENJUALAN!$C$4:$C$4288,'CEK CICI'!A7) -> 358 | J7: =H7-I7 -> -358
A8: =CONCATENATE(B8,E8) -> OTH-LIST04TOYDAI | B8: OTH-LIST04 | C8: List Kaca Depan Code 04 | D8: OTH | E8: TOYDAI | H8: =SUMIFS(X!$F$5:$F$2005,X!$D$5:$D$2005,'CEK CICI'!A8) -> 60 | I8: =SUMIFS(PENJUALAN!$E$4:$E$4288,PENJUALAN!$C$4:$C$4288,'CEK CICI'!A8) -> 58 | J8: =H8-I8 -> 2 | M8: 2
A9: =CONCATENATE(B9,E9) -> OTH-LIST11TOYDAI | B9: OTH-LIST11 | C9: List Kaca Depan Code 11 | D9: OTH | E9: TOYDAI | H9: =SUMIFS(X!$F$5:$F$2005,X!$D$5:$D$2005,'CEK CICI'!A9) -> 37 | I9: =SUMIFS(PENJUALAN!$E$4:$E$4288,PENJUALAN!$C$4:$C$4288,'CEK CICI'!A9) -> 32 | J9: =H9-I9 -> 5 | M9: 2
A10: =CONCATENATE(B10,E10) -> OTH-LISTINVTOY | B10: OTH-LISTINV | C10: List Kaca Depan INV | D10: OTH | E10: TOY | H10: =SUMIFS(X!$F$5:$F$2005,X!$D$5:$D$2005,'CEK CICI'!A10) -> 30 | I10: =SUMIFS(PENJUALAN!$E$4:$E$4288,PENJUALAN!$C$4:$C$4288,'CEK CICI'!A10) -> 27 | J10: =H10-I10 -> 3 | M10: 2
A11: =CONCATENATE(B11,E11) -> OTH-LISTWSERT12SGP | B11: OTH-LISTWSERT12 | C11: List Kaca Depan Ertiga 2012-2018 SGP | D11: OTH | E11: SGP | H11: =SUMIFS(X!$F$5:$F$2005,X!$D$5:$D$2005,'CEK CICI'!A11) -> 2 | I11: =SUMIFS(PENJUALAN!$E$4:$E$4288,PENJUALAN!$C$4:$C$4288,'CEK CICI'!A11) -> 2 | J11: =H11-I11 -> 0
A12: =CONCATENATE(B12,E12) -> OTH-LISTPJR16MIT | B12: OTH-LISTPJR16 | C12: List Kaca Depan Mitsubishi Pajero 16- / Triton 16- | D12: OTH | E12: MIT | H12: =SUMIFS(X!$F$5:$F$2005,X!$D$5:$D$2005,'CEK CICI'!A12) -> 2 | I12: =SUMIFS(PENJUALAN!$E$4:$E$4288,PENJUALAN!$C$4:$C$4288,'CEK CICI'!A12) -> 1 | J12: =H12-I12 -> 1
A13: =CONCATENATE(B13,E13) -> OTH-RPLXLFW | B13: OTH-RPLX | C13: Pemasangan Kaca Mobil Depan | D13: OTH | E13: LFW | H13: =SUMIFS(X!$F$5:$F$2005,X!$D$5:$D$2005,'CEK CICI'!A13) -> 0 | I13: =SUMIFS(PENJUALAN!$E$4:$E$4288,PENJUALAN!$C$4:$C$4288,'CEK CICI'!A13) -> 101 | J13: =H13-I13 -> -101 | M13: 100
A14: =CONCATENATE(B14,E14) -> OTH-RPLXTRW | B14: OTH-RPLX | C14: Pemasangan Kaca Mobil Belakang | D14: OTH | E14: TRW | H14: =SUMIFS(X!$F$5:$F$2005,X!$D$5:$D$2005,'CEK CICI'!A14) -> 0 | I14: =SUMIFS(PENJUALAN!$E$4:$E$4288,PENJUALAN!$C$4:$C$4288,'CEK CICI'!A14) -> 26 | J14: =H14-I14 -> -26 | M14: 100
A15: =CONCATENATE(B15,E15) -> OTH-RPLXSIDE | B15: OTH-RPLX | C15: Pemasangan Kaca Mobil Samping | D15: OTH | E15: SIDE | H15: =SUMIFS(X!$F$5:$F$2005,X!$D$5:$D$2005,'CEK CICI'!A15) -> 0 | I15: =SUMIFS(PENJUALAN!$E$4:$E$4288,PENJUALAN!$C$4:$C$4288,'CEK CICI'!A15) -> 12 | J15: =H15-I15 -> -12 | M15: 100
A16: =CONCATENATE(B16,E16) -> OTH-SERLMB | B16: OTH-SER | C16: Lembur | D16: OTH | E16: LMB | H16: =SUMIFS(X!$F$5:$F$2005,X!$D$5:$D$2005,'CEK CICI'!A16) -> 0 | I16: =SUMIFS(PENJUALAN!$E$4:$E$4288,PENJUALAN!$C$4:$C$4288,'CEK CICI'!A16) -> 37 | J16: =H16-I16 -> -37
A17: =CONCATENATE(B17,E17) -> FILM-40STD | B17: FILM-40 | C17: Automotive Film Standard - Black 40% | D17: FILM | E17: STD | H17: =SUMIFS(X!$F$5:$F$2005,X!$D$5:$D$2005,'CEK CICI'!A17) -> 0 | I17: =SUMIFS(PENJUALAN!$E$4:$E$4288,PENJUALAN!$C$4:$C$4288,'CEK CICI'!A17) -> 17 | J17: =H17-I17 -> -17
A18: =CONCATENATE(B18,E18) -> TRW-AVANZA03HAUTO | B18: TRW-AVANZA03H | C18: Toyota Avanza / Xenia 03-11 1st Gen | D18: TRW | E18: AUTO | F18: X/H | H18: =SUMIFS(X!$F$5:$F$2005,X!$D$5:$D$2005,'CEK CICI'!A18) -> 0 | I18: =SUMIFS(PENJUALAN!$E$4:$E$4288,PENJUALAN!$C$4:$C$4288,'CEK CICI'!A18) -> 0 | J18: =H18-I18 -> 0
A19: =CONCATENATE(B19,E19) -> RDR-CRV12SG | B19: RDR-CRV12 | C19: Honda CR-V 12-16 4th Gen | D19: RDR | E19: SG | H19: =SUMIFS(X!$F$5:$F$2005,X!$D$5:$D$2005,'CEK CICI'!A19) -> 0 | I19: =SUMIFS(PENJUALAN!$E$4:$E$4288,PENJUALAN!$C$4:$C$4288,'CEK CICI'!A19) -> 0 | J19: =H19-I19 -> 0
A20: =CONCATENATE(B20,E20) -> LFW-ALPHARD08RSPIL | B20: LFW-ALPHARD08RS | C20: Toyota Alphard 08-15 ANH20 2nd Gen | D20: LFW | E20: PIL | F20: X/MB/RS | H20: =SUMIFS(X!$F$5:$F$2005,X!$D$5:$D$2005,'CEK CICI'!A20) -> 0 | I20: =SUMIFS(PENJUALAN!$E$4:$E$4288,PENJUALAN!$C$4:$C$4288,'CEK CICI'!A20) -> 0 | J20: =H20-I20 -> 0
A21: =CONCATENATE(B21,E21) -> RDL-AVANZA03ASH | B21: RDL-AVANZA03 | C21: Toyota Avanza / Xenia 03-11 1st Gen | D21: RDL | E21: ASH | H21: =SUMIFS(X!$F$5:$F$2005,X!$D$5:$D$2005,'CEK CICI'!A21) -> 5 | I21: =SUMIFS(PENJUALAN!$E$4:$E$4288,PENJUALAN!$C$4:$C$4288,'CEK CICI'!A21) -> 3 | J21: =H21-I21 -> 2 | K21: A13T4
A22: =CONCATENATE(B22,E22) -> RDR-AVANZA11ASH | B22: RDR-AVANZA11 | C22: Toyota Avanza / Xenia 11-15 2nd Gen | D22: RDR | E22: ASH | H22: =SUMIFS(X!$F$5:$F$2005,X!$D$5:$D$2005,'CEK CICI'!A22) -> 10 | I22: =SUMIFS(PENJUALAN!$E$4:$E$4288,PENJUALAN!$C$4:$C$4288,'CEK CICI'!A22) -> 9 | J22: =H22-I22 -> 1 | K22: A14T3
A23: =CONCATENATE(B23,E23) -> RDL-AVANZA11ASH | B23: RDL-AVANZA11 | C23: Toyota Avanza / Xenia 11-15 2nd Gen | D23: RDL | E23: ASH | H23: =SUMIFS(X!$F$5:$F$2005,X!$D$5:$D$2005,'CEK CICI'!A23) -> 5 | I23: =SUMIFS(PENJUALAN!$E$4:$E$4288,PENJUALAN!$C$4:$C$4288,'CEK CICI'!A23) -> 3 | J23: =H23-I23 -> 2 | K23: A14T3
A24: =CONCATENATE(B24,E24) -> TRW-AVANZA11ORI | B24: TRW-AVANZA11 | C24: Toyota Avanza / Xenia 11-15 2nd Gen/3rd Gen | D24: TRW | E24: ORI | F24: X/Logo | H24: =SUMIFS(X!$F$5:$F$2005,X!$D$5:$D$2005,'CEK CICI'!A24) -> 0 | I24: =SUMIFS(PENJUALAN!$E$4:$E$4288,PENJUALAN!$C$4:$C$4288,'CEK CICI'!A24) -> 0 | J24: =H24-I24 -> 0
A25: =CONCATENATE(B25,E25) -> RDL-AVANZA11ORI | B25: RDL-AVANZA11 | C25: Toyota Avanza / Xenia 11-15 2nd Gen/3rd Gen | D25: RDL | E25: ORI | H25: =SUMIFS(X!$F$5:$F$2005,X!$D$5:$D$2005,'CEK CICI'!A25) -> 0 | I25: =SUMIFS(PENJUALAN!$E$4:$E$4288,PENJUALAN!$C$4:$C$4288,'CEK CICI'!A25) -> 0 | J25: =H25-I25 -> 0
A26: =CONCATENATE(B26,E26) -> RDR-AVANZA11ORI | B26: RDR-AVANZA11 | C26: Toyota Avanza / Xenia 11-15 2nd Gen/3rd Gen | D26: RDR | E26: ORI | H26: =SUMIFS(X!$F$5:$F$2005,X!$D$5:$D$2005,'CEK CICI'!A26) -> 0 | I26: =SUMIFS(PENJUALAN!$E$4:$E$4288,PENJUALAN!$C$4:$C$4288,'CEK CICI'!A26) -> 0 | J26: =H26-I26 -> 0
A27: =CONCATENATE(B27,E27) -> FDL-AVANZA11ORI | B27: FDL-AVANZA11 | C27: Toyota Avanza / Xenia 11-15 2nd Gen/3rd Gen | D27: FDL | E27: ORI | H27: =SUMIFS(X!$F$5:$F$2005,X!$D$5:$D$2005,'CEK CICI'!A27) -> 0 | I27: =SUMIFS(PENJUALAN!$E$4:$E$4288,PENJUALAN!$C$4:$C$4288,'CEK CICI'!A27) -> 0 | J27: =H27-I27 -> 0
A28: =CONCATENATE(B28,E28) -> FDR-AVANZA11ORI | B28: FDR-AVANZA11 | C28: Toyota Avanza / Xenia 11-15 2nd Gen/3rd Gen | D28: FDR | E28: ORI | H28: =SUMIFS(X!$F$5:$F$2005,X!$D$5:$D$2005,'CEK CICI'!A28) -> 0 | I28: =SUMIFS(PENJUALAN!$E$4:$E$4288,PENJUALAN!$C$4:$C$4288,'CEK CICI'!A28) -> 0 | J28: =H28-I28 -> 0
A29: =CONCATENATE(B29,E29) -> LFW-ETIOSASH | B29: LFW-ETIOS | C29: Toyota Etios 10- 1st Gen Sedan | D29: LFW | E29: ASH | F29: X | H29: =SUMIFS(X!$F$5:$F$2005,X!$D$5:$D$2005,'CEK CICI'!A29) -> 0 | I29: =SUMIFS(PENJUALAN!$E$4:$E$4288,PENJUALAN!$C$4:$C$4288,'CEK CICI'!A29) -> 0 | J29: =H29-I29 -> 0 | M29: 1
A30: =CONCATENATE(B30,E30) -> TRW-LUXIODAIHATSU | B30: TRW-LUXIO | C30: Daihatsu Luxio 07- | D30: TRW | E30: DAIHATSU | F30: X/Logo | H30: =SUMIFS(X!$F$5:$F$2005,X!$D$5:$D$2005,'CEK CICI'!A30) -> 12 | I30: =SUMIFS(PENJUALAN!$E$4:$E$4288,PENJUALAN!$C$4:$C$4288,'CEK CICI'!A30) -> 7 | J30: =H30-I30 -> 5 | K30: B8T3 | M30: 1
A31: =CONCATENATE(B31,E31) -> SWR-RAIZEORI | B31: SWR-RAIZE | C31: Toyota Raize / Daihatsu Rocky 20- | D31: SWR | E31: ORI | F31: X | H31: =SUMIFS(X!$F$5:$F$2005,X!$D$5:$D$2005,'CEK CICI'!A31) -> 0 | I31: =SUMIFS(PENJUALAN!$E$4:$E$4288,PENJUALAN!$C$4:$C$4288,'CEK CICI'!A31) -> 0 | J31: =H31-I31 -> 0 | M31: 1
A32: =CONCATENATE(B32,E32) -> TRW-BRV16HONDA | B32: TRW-BRV16 | C32: Honda BR-V 16- Genuine | D32: TRW | E32: HONDA | F32: X/H/Logo | H32: =SUMIFS(X!$F$5:$F$2005,X!$D$5:$D$2005,'CEK CICI'!A32) -> 0 | I32: =SUMIFS(PENJUALAN!$E$4:$E$4288,PENJUALAN!$C$4:$C$4288,'CEK CICI'!A32) -> 0 | J32: =H32-I32 -> 0 | M32: 1
