Workbook
Name Stock: 'Current Stock'!$A:$N
Name kirim: #REF!
Name Tugas: #REF!
Name stockKJD: 'Current Stock'!$A$2:$J$2156
Name StockAll: 'Current Stock'!$A$1:$N$2165
Name BGI: #REF!
Name Penjualan: PENJUALAN!$A$4:$I$10719
Name hpp: #REF!
Name NamedRange1: 'Current Stock'!$1:$2934

Sheet Current Stock
A1: Kode | B1: Kode Mobil | C1: Tipe Mobil | D1: Part | E1: Merk | F1: Aksesoris | G1: SO | H1: Masuk | I1: Keluar | J1: Stok Akhir | K1: Rak | L1: SO | M1: Alert | N1: Lain - Lain
A2: =CONCATENATE(B2,E2) -> OTH-SEALANTXYG | B2: OTH-SEALANT | C2: Sealant Polyurethane XYG Tube | D2: OTH | E2: XYG | H2: =SUMIFS(X!$F$3:$F$5978,X!$D$3:$D$5978,'Current Stock'!A2) -> 0 | I2: =SUMIFS(PENJUALAN!$E$4:$E$3651,PENJUALAN!$C$4:$C$3651,'Current Stock'!A2) -> 0 | J2: =H2-I2 -> 0 | M2: 10
A3: =CONCATENATE(B3,E3) -> OTH-PETIKAYU | B3: OTH-PETI | C3: Peti Kayu | D3: OTH | E3: KAYU | G3: 45988 | H3: =SUMIFS(X!$F$3:$F$5978,X!$D$3:$D$5978,'Current Stock'!A3) -> 1 | I3: =SUMIFS(PENJUALAN!$E$4:$E$3651,PENJUALAN!$C$4:$C$3651,'Current Stock'!A3) -> 27 | J3: =H3-I3 -> -26 | M3: 10
A4: =CONCATENATE(B4,E4) -> OTH-SERTR | B4: OTH-SER | C4: 9092 Sealant Application | D4: OTH | E4: TR | H4: =SUMIFS(X!$F$3:$F$5978,X!$D$3:$D$5978,'Current Stock'!A4) -> 0 | I4: =SUMIFS(PENJUALAN!$E$4:$E$3651,PENJUALAN!$C$4:$C$3651,'Current Stock'!A4) -> 0 | J4: =H4-I4 -> 0
A5: =CONCATENATE(B5,E5) -> OTH-SERBY | B5: OTH-SER | C5: 501 Sealant Application | D5: OTH | E5: BY | G5: 45988 | H5: =SUMIFS(X!$F$3:$F$5978,X!$D$3:$D$5978,'Current Stock'!A5) -> 1540 | I5: =SUMIFS(PENJUALAN!$E$4:$E$3651,PENJUALAN!$C$4:$C$3651,'Current Stock'!A5) -> 270 | J5: =H5-I5 -> 1270
A6: =CONCATENATE(B6,E6) -> OTH-SERSK | B6: OTH-SER | C6: 255 Ultra + Actv-100 Application | D6: OTH | E6: SK | G6: 45988 | H6: =SUMIFS(X!$F$3:$F$5978,X!$D$3:$D$5978,'Current Stock'!A6) -> 90 | I6: =SUMIFS(PENJUALAN!$E$4:$E$3651,PENJUALAN!$C$4:$C$3651,'Current Stock'!A6) -> 84 | J6: =H6-I6 -> 6
A7: =CONCATENATE(B7,E7) -> OTH-SEROTO | B7: OTH-SER | C7: Otoseal Sealant Application | D7: OTH | E7: OTO | H7: =SUMIFS(X!$F$3:$F$5978,X!$D$3:$D$5978,'Current Stock'!A7) -> 5 | I7: =SUMIFS(PENJUALAN!$E$4:$E$3651,PENJUALAN!$C$4:$C$3651,'Current Stock'!A7) -> 0 | J7: =H7-I7 -> 5
A8: =CONCATENATE(B8,E8) -> OTH-SERTRANSPORT | B8: OTH-SER | C8: Transport | D8: OTH | E8: TRANSPORT | G8: 45988 | H8: =SUMIFS(X!$F$3:$F$5978,X!$D$3:$D$5978,'Current Stock'!A8) -> 1 | I8: =SUMIFS(PENJUALAN!$E$4:$E$3651,PENJUALAN!$C$4:$C$3651,'Current Stock'!A8) -> 479 | J8: =H8-I8 -> -478
A9: =CONCATENATE(B9,E9) -> OTH-LIST04TOYDAI | B9: OTH-LIST04 | C9: List Kaca Depan Code 04 | D9: OTH | E9: TOYDAI | G9: 45988 | H9: =SUMIFS(X!$F$3:$F$5978,X!$D$3:$D$5978,'Current Stock'!A9) -> 57 | I9: =SUMIFS(PENJUALAN!$E$4:$E$3651,PENJUALAN!$C$4:$C$3651,'Current Stock'!A9) -> 31 | J9: =H9-I9 -> 26 | M9: 2
A10: =CONCATENATE(B10,E10) -> OTH-LIST11TOYDAI | B10: OTH-LIST11 | C10: List Kaca Depan Code 11 | D10: OTH | E10: TOYDAI | G10: 45988 | H10: =SUMIFS(X!$F$3:$F$5978,X!$D$3:$D$5978,'Current Stock'!A10) -> 35 | I10: =SUMIFS(PENJUALAN!$E$4:$E$3651,PENJUALAN!$C$4:$C$3651,'Current Stock'!A10) -> 22 | J10: =H10-I10 -> 13 | M10: 2
A11: =CONCATENATE(B11,E11) -> OTH-LISTINVTOY | B11: OTH-LISTINV | C11: List Kaca Depan INV | D11: OTH | E11: TOY | G11: 45988 | H11: =SUMIFS(X!$F$3:$F$5978,X!$D$3:$D$5978,'Current Stock'!A11) -> 25 | I11: =SUMIFS(PENJUALAN!$E$4:$E$3651,PENJUALAN!$C$4:$C$3651,'Current Stock'!A11) -> 19 | J11: =H11-I11 -> 6 | M11: 2
A12: =CONCATENATE(B12,E12) -> OTH-LISTWSERT12SGP | B12: OTH-LISTWSERT12 | C12: List Kaca Depan Ertiga 2012-2018 SGP | D12: OTH | E12: SGP | H12: =SUMIFS(X!$F$3:$F$5978,X!$D$3:$D$5978,'Current Stock'!A12) -> 0 | I12: =SUMIFS(PENJUALAN!$E$4:$E$3651,PENJUALAN!$C$4:$C$3651,'Current Stock'!A12) -> 0 | J12: =H12-I12 -> 0
A13: =CONCATENATE(B13,E13) -> MLDG-LFWHRV14UPHON | B13: MLDG-LFWHRV14UP | C13: Moulding List Honda HR-V 14-21 5D SUV (Upper) | D13: MLDG | E13: HON | G13: 45988 | H13: =SUMIFS(X!$F$3:$F$5978,X!$D$3:$D$5978,'Current Stock'!A13) -> 2 | I13: =SUMIFS(PENJUALAN!$E$4:$E$3651,PENJUALAN!$C$4:$C$3651,'Current Stock'!A13) -> 1 | J13: =H13-I13 -> 1
A14: =CONCATENATE(B14,E14) -> MLDG-LFWHRV14SIDEHON | B14: MLDG-LFWHRV14SIDE | C14: Moulding List Honda HR-V 14-21 5D SUV (Side) | D14: MLDG | E14: HON | G14: 45988 | H14: =SUMIFS(X!$F$3:$F$5978,X!$D$3:$D$5978,'Current Stock'!A14) -> 4 | I14: =SUMIFS(PENJUALAN!$E$4:$E$3651,PENJUALAN!$C$4:$C$3651,'Current Stock'!A14) -> 2 | J14: =H14-I14 -> 2
A15: =CONCATENATE(B15,E15) -> MLDG-ANH20AGH30UPTOY | B15: MLDG-ANH20AGH30UP | C15: Moulding List Alphard ANH20 AGH30 (Upper) | D15: MLDG | E15: TOY | H15: =SUMIFS(X!$F$3:$F$5978,X!$D$3:$D$5978,'Current Stock'!A15) -> 1 | I15: =SUMIFS(PENJUALAN!$E$4:$E$3651,PENJUALAN!$C$4:$C$3651,'Current Stock'!A15) -> 1 | J15: =H15-I15 -> 0
A16: =CONCATENATE(B16,E16) -> MLDG-LFWFE700MIT | B16: MLDG-LFWFE700 | C16: Moulding List Mitsubishi Canter FE700 01- (PS110,125) (Windshield) | D16: MLDG | E16: MIT | H16: =SUMIFS(X!$F$3:$F$5978,X!$D$3:$D$5978,'Current Stock'!A16) -> 1 | I16: =SUMIFS(PENJUALAN!$E$4:$E$3651,PENJUALAN!$C$4:$C$3651,'Current Stock'!A16) -> 1 | J16: =H16-I16 -> 0
A17: =CONCATENATE(B17,E17) -> MLDG-LFWFORTUNER05TOY | B17: MLDG-LFWFORTUNER05 | C17: Moulding List Toyota Fortuner 05-15 1st Gen (Windshield) | D17: MLDG | E17: TOY | H17: =SUMIFS(X!$F$3:$F$5978,X!$D$3:$D$5978,'Current Stock'!A17) -> 0 | I17: =SUMIFS(PENJUALAN!$E$4:$E$3651,PENJUALAN!$C$4:$C$3651,'Current Stock'!A17) -> 1 | J17: =H17-I17 -> -1
A18: =CONCATENATE(B18,E18) -> MLDG-LFWCROSSTREK23SUB | B18: MLDG-LFWCROSSTREK23 | C18: Moulding List Subaru Crosstrek 23- (Windshield) | D18: MLDG | E18: SUB | H18: =SUMIFS(X!$F$3:$F$5978,X!$D$3:$D$5978,'Current Stock'!A18) -> 0 | I18: =SUMIFS(PENJUALAN!$E$4:$E$3651,PENJUALAN!$C$4:$C$3651,'Current Stock'!A18) -> 0 | J18: =H18-I18 -> 0
A19: =CONCATENATE(B19,E19) -> OTH-RPLXLFW | B19: OTH-RPLX | C19: Bongkar Pasang Kaca Mobil Depan | D19: OTH | E19: LFW | G19: 45988 | H19: =SUMIFS(X!$F$3:$F$5978,X!$D$3:$D$5978,'Current Stock'!A19) -> 0 | I19: =SUMIFS(PENJUALAN!$E$4:$E$3651,PENJUALAN!$C$4:$C$3651,'Current Stock'!A19) -> 52 | J19: =H19-I19 -> -52 | M19: 100
A20: =CONCATENATE(B20,E20) -> OTH-RPLXTRW | B20: OTH-RPLX | C20: Bongkar Pasang Kaca Mobil Belakang | D20: OTH | E20: TRW | G20: 45988 | H20: =SUMIFS(X!$F$3:$F$5978,X!$D$3:$D$5978,'Current Stock'!A20) -> 0 | I20: =SUMIFS(PENJUALAN!$E$4:$E$3651,PENJUALAN!$C$4:$C$3651,'Current Stock'!A20) -> 12 | J20: =H20-I20 -> -12 | M20: 100
A21: =CONCATENATE(B21,E21) -> OTH-RPLXSIDE | B21: OTH-RPLX | C21: Bongkar Pasang Kaca Mobil Samping | D21: OTH | E21: SIDE | G21: 45988 | H21: =SUMIFS(X!$F$3:$F$5978,X!$D$3:$D$5978,'Current Stock'!A21) -> 0 | I21: =SUMIFS(PENJUALAN!$E$4:$E$3651,PENJUALAN!$C$4:$C$3651,'Current Stock'!A21) -> 12 | J21: =H21-I21 -> -12 | M21: 100
A22: =CONCATENATE(B22,E22) -> OTH-SERLMB | B22: OTH-SER | C22: Lembur | D22: OTH | E22: LMB | G22: 45988 | H22: =SUMIFS(X!$F$3:$F$5978,X!$D$3:$D$5978,'Current Stock'!A22) -> 15 | I22: =SUMIFS(PENJUALAN!$E$4:$E$3651,PENJUALAN!$C$4:$C$3651,'Current Stock'!A22) -> 77 | J22: =H22-I22 -> -62
A23: =CONCATENATE(B23,E23) -> OTH-CKC | B23: OTH-C | C23: Biaya Pengecekan | D23: OTH | E23: KC | G23: 45988 | H23: =SUMIFS(X!$F$3:$F$5978,X!$D$3:$D$5978,'Current Stock'!A23) -> 0 | I23: =SUMIFS(PENJUALAN!$E$4:$E$3651,PENJUALAN!$C$4:$C$3651,'Current Stock'!A23) -> 15 | J23: =H23-I23 -> -15
A24: =CONCATENATE(B24,E24) -> FILM-40STD | B24: FILM-40 | C24: Automotive Film Standard - Black 40% | D24: FILM | E24: STD | H24: =SUMIFS(X!$F$3:$F$5978,X!$D$3:$D$5978,'Current Stock'!A24) -> 0 | I24: =SUMIFS(PENJUALAN!$E$4:$E$3651,PENJUALAN!$C$4:$C$3651,'Current Stock'!A24) -> 41 | J24: =H24-I24 -> -41
A25: =CONCATENATE(B25,E25) -> FILM-60STD | B25: FILM-60 | C25: Automotive Film Standard - Black 40% | D25: FILM | E25: STD | G25: 45988 | H25: =SUMIFS(X!$F$3:$F$5978,X!$D$3:$D$5978,'Current Stock'!A25) -> 33 | I25: =SUMIFS(PENJUALAN!$E$4:$E$3651,PENJUALAN!$C$4:$C$3651,'Current Stock'!A25) -> 48 | J25: =H25-I25 -> -15
A26: =CONCATENATE(B26,E26) -> FILM-80STD | B26: FILM-80 | C26: Automotive Film Standard - Black 80% | D26: FILM | E26: STD | H26: =SUMIFS(X!$F$3:$F$5978,X!$D$3:$D$5978,'Current Stock'!A26) -> 1 | I26: =SUMIFS(PENJUALAN!$E$4:$E$3651,PENJUALAN!$C$4:$C$3651,'Current Stock'!A26) -> 13 | J26: =H26-I26 -> -12
A27: =CONCATENATE(B27,E27) -> FILM-BPSG | B27: FILM-BP | C27: Black Phantom Solar Gard | D27: FILM | E27: SG | G27: 45988 | H27: =SUMIFS(X!$F$3:$F$5978,X!$D$3:$D$5978,'Current Stock'!A27) -> 15 | I27: =SUMIFS(PENJUALAN!$E$4:$E$3651,PENJUALAN!$C$4:$C$3651,'Current Stock'!A27) -> 19 | J27: =H27-I27 -> -4
A28: =CONCATENATE(B28,E28) -> TRW-AVANZA03HAUTO | B28: TRW-AVANZA03H | C28: Toyota Avanza / Xenia 03-11 1st Gen | D28: TRW | E28: AUTO | F28: X/H | H28: =SUMIFS(X!$F$3:$F$5978,X!$D$3:$D$5978,'Current Stock'!A28) -> 0 | I28: =SUMIFS(PENJUALAN!$E$4:$E$3651,PENJUALAN!$C$4:$C$3651,'Current Stock'!A28) -> 0 | J28: =H28-I28 -> 0
A29: =CONCATENATE(B29,E29) -> RDR-CRV12SG | B29: RDR-CRV12 | C29: Honda CR-V 12-16 4th Gen | D29: RDR | E29: SG | H29: =SUMIFS(X!$F$3:$F$5978,X!$D$3:$D$5978,'Current Stock'!A29) -> 0 | I29: =SUMIFS(PENJUALAN!$E$4:$E$3651,PENJUALAN!$C$4:$C$3651,'Current Stock'!A29) -> 0 | J29: =H29-I29 -> 0
A30: =CONCATENATE(B30,E30) -> LFW-ALPHARD08RSPIL | B30: LFW-ALPHARD08RS | C30: Toyota Alphard 08-15 ANH20 2nd Gen | D30: LFW | E30: PIL | F30: X/MB/RS | H30: =SUMIFS(X!$F$3:$F$5978,X!$D$3:$D$5978,'Current Stock'!A30) -> 2 | I30: =SUMIFS(PENJUALAN!$E$4:$E$3651,PENJUALAN!$C$4:$C$3651,'Current Stock'!A30) -> 2 | J30: =H30-I30 -> 0
A31: =CONCATENATE(B31,E31) -> RDL-AVANZA03ASH | B31: RDL-AVANZA03 | C31: Toyota Avanza / Xenia 03-11 1st Gen | D31: RDL | E31: ASH | H31: =SUMIFS(X!$F$3:$F$5978,X!$D$3:$D$5978,'Current Stock'!A31) -> 1 | I31: =SUMIFS(PENJUALAN!$E$4:$E$3651,PENJUALAN!$C$4:$C$3651,'Current Stock'!A31) -> 0 | J31: =H31-I31 -> 1
A32: =CONCATENATE(B32,E32) -> RDR-AVANZA11ASH | B32: RDR-AVANZA11 | C32: Toyota Avanza / Xenia 11-15 2nd Gen/3rd Gen | D32: RDR | E32: ASH | G32: 45988 | H32: =SUMIFS(X!$F$3:$F$5978,X!$D$3:$D$5978,'Current Stock'!A32) -> 4 | I32: =SUMIFS(PENJUALAN!$E$4:$E$3651,PENJUALAN!$C$4:$C$3651,'Current Stock'!A32) -> 4 | J32: =H32-I32 -> 0 | K32: D1T3
A33: =CONCATENATE(B33,E33) -> RDL-AVANZA11ASH | B33: RDL-AVANZA11 | C33: Toyota Avanza / Xenia 11-15 2nd Gen/3rd Gen | D33: RDL | E33: ASH | H33: =SUMIFS(X!$F$3:$F$5978,X!$D$3:$D$5978,'Current Stock'!A33) -> 0 | I33: =SUMIFS(PENJUALAN!$E$4:$E$3651,PENJUALAN!$C$4:$C$3651,'Current Stock'!A33) -> 0 | J33: =H33-I33 -> 0
A34: =CONCATENATE(B34,E34) -> TRW-AVANZA11ORI | B34: TRW-AVANZA11 | C34: Toyota Avanza / Xenia 11-15 2nd Gen/3rd Gen | D34: TRW | E34: ORI | F34: X/Logo | H34: =SUMIFS(X!$F$3:$F$5978,X!$D$3:$D$5978,'Current Stock'!A34) -> 0 | I34: =SUMIFS(PENJUALAN!$E$4:$E$3651,PENJUALAN!$C$4:$C$3651,'Current Stock'!A34) -> 0 | J34: =H34-I34 -> 0
A35: =CONCATENATE(B35,E35) -> RDL-AVANZA11AGC | B35: RDL-AVANZA11 | C35: Toyota Avanza / Xenia 11-15 2nd Gen/3rd Gen | D35: RDL | E35: AGC | H35: =SUMIFS(X!$F$3:$F$5978,X!$D$3:$D$5978,'Current Stock'!A35) -> 0 | I35: =SUMIFS(PENJUALAN!$E$4:$E$3651,PENJUALAN!$C$4:$C$3651,'Current Stock'!A35) -> 0 | J35: =H35-I35 -> 0
A36: =CONCATENATE(B36,E36) -> RDR-AVANZA11ACG | B36: RDR-AVANZA11 | C36: Toyota Avanza / Xenia 11-15 2nd Gen/3rd Gen | D36: RDR | E36: ACG | H36: =SUMIFS(X!$F$3:$F$5978,X!$D$3:$D$5978,'Current Stock'!A36) -> 0 | I36: =SUMIFS(PENJUALAN!$E$4:$E$3651,PENJUALAN!$C$4:$C$3651,'Current Stock'!A36) -> 0 | J36: =H36-I36 -> 0
A37: =CONCATENATE(B37,E37) -> FDL-AVANZA11ACG | B37: FDL-AVANZA11 | C37: Toyota Avanza / Xenia 11-15 2nd Gen/3rd Gen | D37: FDL | E37: ACG | H37: =SUMIFS(X!$F$3:$F$5978,X!$D$3:$D$5978,'Current Stock'!A37) -> 0 | I37: =SUMIFS(PENJUALAN!$E$4:$E$3651,PENJUALAN!$C$4:$C$3651,'Current Stock'!A37) -> 0 | J37: =H37-I37 -> 0
A38: =CONCATENATE(B38,E38) -> FDR-AVANZA11ACG | B38: FDR-AVANZA11 | C38: Toyota Avanza / Xenia 11-15 2nd Gen/3rd Gen | D38: FDR | E38: ACG | H38: =SUMIFS(X!$F$3:$F$5978,X!$D$3:$D$5978,'Current Stock'!A38) -> 0 | I38: =SUMIFS(PENJUALAN!$E$4:$E$3651,PENJUALAN!$C$4:$C$3651,'Current Stock'!A38) -> 0 | J38: =H38-I38 -> 0
A39: =CONCATENATE(B39,E39) -> LFW-ETIOSASH | B39: LFW-ETIOS | C39: Toyota Etios 10- 1st Gen Sedan | D39: LFW | E39: ASH | F39: X | H39: =SUMIFS(X!$F$3:$F$5978,X!$D$3:$D$5978,'Current Stock'!A39) -> 0 | I39: =SUMIFS(PENJUALAN!$E$4:$E$3651,PENJUALAN!$C$4:$C$3651,'Current Stock'!A39) -> 0 | J39: =H39-I39 -> 0 | M39: 1
A40: =CONCATENATE(B40,E40) -> TRW-LUXIODAIHATSU | B40: TRW-LUXIO | C40: Daihatsu Luxio 07- | D40: TRW | E40: DAIHATSU | F40: X/Logo | G40: 45988 | H40: =SUMIFS(X!$F$3:$F$5978,X!$D$3:$D$5978,'Current Stock'!A40) -> 29 | I40: =SUMIFS(PENJUALAN!$E$4:$E$3651,PENJUALAN!$C$4:$C$3651,'Current Stock'!A40) -> 20 | J40: =H40-I40 -> 9 | K40: A3T3 | M40: 1
...

Sheet PENJUALAN
A2: TANGGAL | B2: INV | C2: PRODUK | E2: PC | F2: Penjualan | K2: Konsumen | P2: Sales via | Q2: Pembayaran | X2: Input By | Y2: RIAN | Z2: Check
C3: KODE | D3: NAMA | F3: Satuan | G3: Jumlah | H3: Diskon | I3: Nett | J3: Jumlah | K3: Nama | L3: No Telp | M3: Email | N3: No Pol | O3: Alamat | Q3: TUNAI | R3: DP TUNAI | S3: DP TF | T3: TRANSFER | U3: TOKPED | V3: POTONG | W3: Kembali
A4: 45719 | B4: C250001 | C4: LFW-ALMAZRSXYG | D4: =IFERROR(VLOOKUP(C4,Stock,3,FALSE),"") -> Wuling Almaz (Sensor) | E4: 1 | F4: 3150000 | G4: =E4*F4 -> 3150000 | H4: 150000 | I4: =G4-H4 -> 3000000 | J4: =I4 -> 3000000 | K4: Rudi | L4: +62 818-213-689 | N4: B 869 RS | O4: BSD | P4: GOOGLE | T4: 3000000 | X4: CM | Z4: TF 388
A5: 45721 | B5: C250002 | C5: LFW-TIMORMU | D5: =IFERROR(VLOOKUP(C5,Stock,3,FALSE),"") -> Kia Timor 95-98 / Sephia 94-05 | E5: 1 | F5: 1480000 | G5: =E5*F5 -> 1480000 | I5: =G5-H5 -> 1480000 | J5: =I5 -> 1480000 | K5: Icshan | L5: +62 812-8854-6009 | O5: Pondok Aren | P5: GOOGLE | T5: 130000 | Z5: DP 130K TF
A6: 45721 | B6: C250002 | C6: OTH-SERTRANSPORT | D6: =IFERROR(VLOOKUP(C6,Stock,3,FALSE),"") -> Transport | E6: 1 | F6: 150000 | G6: =E6*F6 -> 150000 | I6: =G6-H6 -> 150000 | J6: =I6 -> 150000 | K6: Icshan | L6: +62 812-8854-6009 | O6: Pondok Aren | P6: GOOGLE
A7: 45721 | B7: C250003 | C7: TRW-IGNISXYG | D7: =IFERROR(VLOOKUP(C7,Stock,3,FALSE),"") -> Suzuki Ignis 17- | E7: 1 | F7: 1149000 | G7: =E7*F7 -> 1149000 | I7: =G7-H7 -> 1149000 | J7: =I7 -> 1149000 | K7: Rudy Widyanto | L7: +62 816-531-320 | N7: B 2003 BYB | O7: Meruya | P7: GOOGLE
A8: 45722 | B8: C250004 | C8: OTH-RPLXLFW | D8: =IFERROR(VLOOKUP(C8,Stock,3,FALSE),"") -> Bongkar Pasang Kaca Mobil Depan | E8: 1 | F8: 450000 | G8: =E8*F8 -> 450000 | I8: =G8-H8 -> 450000 | J8: =I8 -> 450000 | K8: Gloss Patrol | L8: +62 813-8800-0093 | O8: BSD | P8: GOOGLE | T8: 100000 | Z8: TF 388 100K DENNY KRISANDI
A9: 45722 | B9: C250004 | C9: OTH-RPLXSIDE | D9: =IFERROR(VLOOKUP(C9,Stock,3,FALSE),"") -> Bongkar Pasang Kaca Mobil Samping | E9: 2 | F9: 200000 | G9: =E9*F9 -> 400000 | I9: =G9-H9 -> 400000 | J9: =I9 -> 400000 | K9: Gloss Patrol | L9: +62 813-8800-0093 | O9: BSD | P9: GOOGLE | Z9: TF 388 850K DENNY KRISANDI
A10: 45722 | B10: C250004 | C10: OTH-SERTRANSPORT | D10: =IFERROR(VLOOKUP(C10,Stock,3,FALSE),"") -> Transport | E10: 1 | F10: 100000 | G10: =E10*F10 -> 100000 | I10: =G10-H10 -> 100000 | J10: =I10 -> 100000 | K10: Gloss Patrol | L10: +62 813-8800-0093 | O10: BSD | P10: GOOGLE | Z10: TF 388
A11: 45722 | B11: C250005 | C11: SWL-PAJERO08XYG | D11: =IFERROR(VLOOKUP(C11,Stock,3,FALSE),"") -> Mitsubishi Pajero 08-16 | E11: 1 | F11: 839000 | G11: =E11*F11 -> 839000 | I11: =G11-H11 -> 839000 | J11: =I11 -> 839000 | K11: Togap Parlindungan Simanjuntak | L11: +62 813-8288-8277 | N11: B 1439 NCY | O11: Karang Tengah | P11: GOOGLE | T11: 100000 | Z11: TF 388 100K TOGAP PARLINDUNGAN /
A12: 45722 | B12: C250005 | C12: OTH-SERTRANSPORT | D12: =IFERROR(VLOOKUP(C12,Stock,3,FALSE),"") -> Transport | E12: 1 | F12: 80000 | G12: =E12*F12 -> 80000 | I12: =G12-H12 -> 80000 | J12: =I12 -> 80000 | K12: Togap Parlindungan Simanjuntak | L12: +62 813-8288-8277 | N12: B 1439 NCY | O12: Karang Tengah | P12: GOOGLE
A13: 45722 | B13: C250006 | C13: TRW-SIGRA16MU | D13: =IFERROR(VLOOKUP(C13,Stock,3,FALSE),"") -> Toyota Calya / Sigra 16- | E13: 1 | F13: 850000 | G13: =E13*F13 -> 850000 | I13: =G13-H13 -> 850000 | J13: =I13 -> 850000 | K13: Riki | L13: +62 811-239-870 | O13: Ruko | P13: GOOGLE
A14: 45722 | B14: C250007 | C14: FDR-SIGRA16MU | D14: =IFERROR(VLOOKUP(C14,Stock,3,FALSE),"") -> Toyota Calya / Sigra 16- | E14: 1 | F14: 450000 | G14: =E14*F14 -> 450000 | I14: =G14-H14 -> 450000 | J14: =I14 -> 450000 | K14: Edison | L14: 081288843107 | N14: B 1038 VOF | O14: Tigaraksa | P14: GOOGLE
A15: 45723 | B15: C250008 | C15: LFW-AUDIB811XYG | D15: =IFERROR(VLOOKUP(C15,Stock,3,FALSE),"") -> Audi A4 08-15 B8 [11-15] (1 Sensor / O Sempurna) | E15: 1 | F15: 5081000 | G15: =E15*F15 -> 5081000 | I15: =G15-H15 -> 5081000 | J15: =I15 -> 5081000 | K15: Hamzah Purnama | L15: +62 815-6500-874 | N15: H 1904 T2 | O15: Jakarta Selatan | P15: GOOGLE | T15: 5081000 | X15: lia
A16: 45723 | B16: C250008 | C16: OTH-SERTRANSPORT | D16: =IFERROR(VLOOKUP(C16,Stock,3,FALSE),"") -> Transport | E16: 1 | F16: 250000 | G16: =E16*F16 -> 250000 | I16: =G16-H16 -> 250000 | J16: =I16 -> 250000 | K16: Hamzah Purnama | L16: +62 815-6500-874 | N16: H 1904 T2 | O16: Jakarta Selatan | P16: GOOGLE | T16: 250000 | X16: lia
A17: 45723 | B17: C250009 | C17: TRW-RUSH17HXYG | D17: =IFERROR(VLOOKUP(C17,Stock,3,FALSE),"") -> Toyota Rush / Terios 18- | E17: 1 | F17: 1052000 | G17: =E17*F17 -> 1052000 | I17: =G17-H17 -> 1052000 | J17: =I17 -> 1052000 | K17: Pak Hartono. | L17: +62 817-0705-500 | O17: Tangerang | P17: GOOGLE | T17: 100000 | X17: lia
A18: 45723 | B18: C250009 | C18: OTH-SERTRANSPORT | D18: =IFERROR(VLOOKUP(C18,Stock,3,FALSE),"") -> Transport | E18: 1 | F18: 120000 | G18: =E18*F18 -> 120000 | I18: =G18-H18 -> 120000 | J18: =I18 -> 120000 | K18: Pak Hartono. | L18: +62 817-0705-500 | N18: B 1148 VOQ | O18: Tangerang | P18: GOOGLE | X18: lia
A19: 45724 | B19: C250010 | C19: LFW-VIOS02MU | D19: =IFERROR(VLOOKUP(C19,Stock,3,FALSE),"") -> Toyota Vios 02-07 XP40 1st Gen | E19: 1 | F19: 1455000 | G19: =E19*F19 -> 1455000 | I19: =G19-H19 -> 1455000 | J19: =I19 -> 1455000 | K19: Rika | L19: +62 855-8685-624 | M19: rika26aditya@gmail.com | N19: A 1054 VN | O19: Batuceper | P19: GOOGLE | Q19: 1455000
A20: 45724 | B20: C250011 | C20: LFW-CRV95XYG | D20: =IFERROR(VLOOKUP(C20,Stock,3,FALSE),"") -> Honda CR-V 95-01 1st Gen | E20: 1 | F20: 1600000 | G20: =E20*F20 -> 1600000 | I20: =G20-H20 -> 1600000 | J20: =I20 -> 1600000 | K20: Among | L20: +62 817-6488-584 | M20: aqlylsno@gmail.com | N20: B 8136 T | O20: Kembangan | P20: GOOGLE
A21: 45724 | B21: C250012 | C21: VOID | D21: =IFERROR(VLOOKUP(C21,Stock,3,FALSE),"")
A22: 45724 | B22: C250013 | C22: TRW-AVANZA21HASH | D22: =IFERROR(VLOOKUP(C22,Stock,3,FALSE),"") -> Toyota Avanza / Xenia 21- 4th Gen | E22: 1 | F22: 975000 | G22: =E22*F22 -> 975000 | I22: =G22-H22 -> 975000 | J22: =I22 -> 975000 | K22: Nurjanah Efendy | L22: +62 813-4199-1001 | O22: Tangerang | P22: GOOGLE | Q22: 975000 | Z22: TF 388
A23: 45724 | B23: C250013 | C23: OTH-PETIKAYU | D23: =IFERROR(VLOOKUP(C23,Stock,3,FALSE),"") -> Peti Kayu | E23: 1 | F23: 200000 | G23: =E23*F23 -> 200000 | I23: =G23-H23 -> 200000 | J23: =I23 -> 200000 | K23: Nurjanah Efendy | L23: +62 813-4199-1001 | O23: Tangerang | P23: GOOGLE | Q23: 200000 | Z23: TF 388
A24: 45724 | B24: C250013 | C24: OTH-SERTRANSPORT | D24: =IFERROR(VLOOKUP(C24,Stock,3,FALSE),"") -> Transport | E24: 1 | F24: 150000 | G24: =E24*F24 -> 150000 | I24: =G24-H24 -> 150000 | J24: =I24 -> 150000 | K24: Nurjanah Efendy | L24: +62 813-4199-1001 | O24: Tangerang | P24: GOOGLE | Q24: 150000 | Z24: TF 388
A25: 45726 | B25: C250014 | C25: LFW-CROSSXYG | D25: =IFERROR(VLOOKUP(C25,Stock,3,FALSE),"") -> Toyota Corolla Cross 21- | E25: 1 | F25: 3750000 | G25: =E25*F25 -> 3750000 | I25: =G25-H25 -> 3750000 | J25: =I25 -> 3750000 | K25: P. Brian Wahyu | L25: +62 818-780-808 | O25: Tangerang | P25: GOOGLE | T25: 810000 | X25: lia | Z25: TF 388
A26: 45726 | B26: C250014 | C26: OTH-PETIKAYU | D26: =IFERROR(VLOOKUP(C26,Stock,3,FALSE),"") -> Peti Kayu | E26: 1 | F26: 200000 | G26: =E26*F26 -> 200000 | I26: =G26-H26 -> 200000 | J26: =I26 -> 200000 | K26: P. Brian Wahyu | L26: +62 818-780-808 | O26: Tangerang | P26: GOOGLE | X26: lia | Z26: TF 388
A27: 45726 | B27: C250014 | C27: OTH-SERTRANSPORT | D27: =IFERROR(VLOOKUP(C27,Stock,3,FALSE),"") -> Transport | E27: 1 | F27: 100000 | G27: =E27*F27 -> 100000 | I27: =G27-H27 -> 100000 | J27: =I27 -> 100000 | K27: P. Brian Wahyu | L27: +62 818-780-808 | O27: Tangerang | P27: GOOGLE | X27: lia | Z27: TF 388
A28: 45726 | B28: C250014 | C28: OTH-SERTRANSPORT | D28: =IFERROR(VLOOKUP(C28,Stock,3,FALSE),"") -> Transport | E28: 1 | F28: 388000 | G28: =E28*F28 -> 388000 | I28: =G28-H28 -> 388000 | J28: =I28 -> 388000 | K28: P. Brian Wahyu | L28: +62 818-780-808 | O28: Tangerang | P28: GOOGLE
A29: 45726 | B29: C250015 | C29: LFW-HIACEXYG | D29: =IFERROR(VLOOKUP(C29,Stock,3,FALSE),"") -> Toyota Hi-Ace 04-20 Commuter | E29: 1 | F29: 1759000 | G29: =E29*F29 -> 1759000 | I29: =G29-H29 -> 1759000 | J29: =I29 -> 1759000 | K29: Nirwana reborn | L29: +6287877218668 | O29: Tangerang | P29: GOOGLE | X29: lia
A30: 45726 | B30: C250016 | C30: OTH-RPLXLFW | D30: =IFERROR(VLOOKUP(C30,Stock,3,FALSE),"") -> Bongkar Pasang Kaca Mobil Depan | E30: 1 | F30: 550000 | G30: =E30*F30 -> 550000 | I30: =G30-H30 -> 550000 | J30: =I30 -> 550000 | K30: Fauzan | L30: +62 812-9940-9142 | O30: Tangerang | P30: GOOGLE
A31: 45726 | B31: C250016 | C31: OTH-SERTRANSPORT | D31: =IFERROR(VLOOKUP(C31,Stock,3,FALSE),"") -> Transport | E31: 1 | F31: 80000 | G31: =E31*F31 -> 80000 | I31: =G31-H31 -> 80000 | J31: =I31 -> 80000 | K31: Fauzan | L31: +62 812-9940-9142 | O31: Tangerang | P31: GOOGLE
A32: 45726 | B32: C250017 | C32: TRW-BRIONOLBGXYG | D32: =IFERROR(VLOOKUP(C32,Stock,3,FALSE),"") -> Honda Brio 10-17 [Tanpa Lubang] | E32: 1 | F32: 955000 | G32: =E32*F32 -> 955000 | I32: =G32-H32 -> 955000 | J32: =I32 -> 955000 | K32: Muhammad Haidar | L32: 6282143097683 | O32: Pondok Aren | P32: GOOGLE
A33: 45726 | B33: C250018 | C33: LFW-BIANTEXYG | D33: =IFERROR(VLOOKUP(C33,Stock,3,FALSE),"") -> Mazda Biante 08- | E33: 1 | F33: 3661000 | G33: =E33*F33 -> 3661000 | I33: =G33-H33 -> 3661000 | J33: =I33 -> 3661000 | K33: Fadhan Osti | L33: 08132809993 | M33: fadhan.osti@gmail.com | O33: Tangerang | P33: GOOGLE
A34: 45726 | B34: C250019 | C34: LFW-COROLLA91XYG | D34: =IFERROR(VLOOKUP(C34,Stock,3,FALSE),"") -> Toyota Corolla Great E100 91-96 7th Gen | E34: 1 | F34: 1488000 | G34: =E34*F34 -> 1488000 | I34: =G34-H34 -> 1488000 | J34: =I34 -> 1488000 | O34: Tangerang | P34: Tokped BKS
A35: 45726 | B35: C250020 | C35: TRW-BALENO15XYG | D35: =IFERROR(VLOOKUP(C35,Stock,3,FALSE),"") -> Suzuki Baleno 15-21 | E35: 1 | F35: 1164000 | G35: =E35*F35 -> 1164000 | I35: =G35-H35 -> 1164000 | J35: =I35 -> 1164000 | K35: Chuko Tanah Abang | L35: +62 813-4335-0809 | O35: Jakarta pusat | P35: GOOGLE | T35: 1164000 | X35: lia
A36: 45726 | B36: C250020 | C36: OTH-PETIKAYU | D36: =IFERROR(VLOOKUP(C36,Stock,3,FALSE),"") -> Peti Kayu | E36: 1 | F36: 200000 | G36: =E36*F36 -> 200000 | I36: =G36-H36 -> 200000 | J36: =I36 -> 200000 | K36: Chuko Tanah Abang | L36: +62 813-4335-0809 | O36: Jakarta pusat | P36: GOOGLE | T36: 200000 | X36: lia
A37: 45726 | B37: C250021 | C37: LFW-FORTUNER15MU | D37: =IFERROR(VLOOKUP(C37,Stock,3,FALSE),"") -> Toyota Fortuner 15- 2nd Gen | E37: 1 | F37: 1737000 | G37: =E37*F37 -> 1737000 | I37: =G37-H37 -> 1737000 | J37: =I37 -> 1737000 | K37: Johanes | L37: +62 813-5190-4272 | O37: Tangerang | P37: GOOGLE | T37: 100000
A38: 45726 | B38: C250021 | C38: OTH-SERTRANSPORT | D38: =IFERROR(VLOOKUP(C38,Stock,3,FALSE),"") -> Transport | E38: 1 | F38: 20000 | G38: =E38*F38 -> 20000 | I38: =G38-H38 -> 20000 | J38: =I38 -> 20000 | K38: Johanes | L38: +62 813-5190-4272 | O38: Tangerang | P38: GOOGLE
A39: 45728 | B39: C250022 | C39: LFW-GRANMAXMU | D39: =IFERROR(VLOOKUP(C39,Stock,3,FALSE),"") -> Daihatsu Gran Max / Luxio 07- | E39: 1 | F39: 985000 | G39: =E39*F39 -> 985000 | I39: =G39-H39 -> 985000 | J39: =I39 -> 985000 | K39: Dedy Candra | L39: +6281385045210 | O39: Kamal | P39: GOOGLE | T39: 50000
A40: 45728 | B40: C250022 | C40: OTH-SERTRANSPORT | D40: =IFERROR(VLOOKUP(C40,Stock,3,FALSE),"") -> Transport | E40: 1 | F40: 70000 | G40: =E40*F40 -> 70000 | I40: =G40-H40 -> 70000 | J40: =I40 -> 70000 | K40: Dedy Candra | L40: +6281385045210 | O40: Kamal | P40: GOOGLE
A41: 45728 | B41: C250023 | C41: TRW-SIGRA16MU | D41: =IFERROR(VLOOKUP(C41,Stock,3,FALSE),"") -> Toyota Calya / Sigra 16- | E41: 1 | F41: 850000 | G41: =E41*F41 -> 850000 | I41: =G41-H41 -> 850000 | J41: =I41 -> 850000 | K41: P.Syahril | L41: +6282177528028 | O41: Tangerang | P41: GOOGLE | T41: 100000
...

Sheet Copy of Copy of INV VIRTUAL AME
A1: SENTRA AUTOGLASS TANGERANG | J1: Tanggal | L1: 46132
A2: Ruko Permata Niaga II No. 17, Taman Royal I, Tanah Tinggi, Kota Tangerang 15119 | J2: Kepada Yth.
A3: (+62) 81288009878 | (+62) 81281161200
J4: +62 858-1000-8154
J5: Tangerang
D8: NOTA PENJUALAN
A10: INV | B10: D260129 | J10: NO POL
A11: No | B11: Kode | C11: Nama Barang | H11: Qty | J11: Harga Satuan | L11: Jumlah
A12: 1 | B12: LFW-VOXY17XYG | C12: =IFERROR(VLOOKUP(B12,Stock,3,FALSE),"") -> Toyota Voxy 17- | H12: 1 | I12: PC | J12: 3326000 | L12: =H12*J12 -> 3326000
A13: 2 | B13: FDL-VOXY17AGC | C13: =IFERROR(VLOOKUP(B13,Stock,3,FALSE),"") | H13: 1 | I13: x | J13: 2004000 | L13: =H13*J13 -> 2004000
A14: 3 | C14: =IFERROR(VLOOKUP(B14,Stock,3,FALSE),"") | L14: =H14*J14 -> 0
A15: 4 | C15: =IFERROR(VLOOKUP(B15,Stock,3,FALSE),"") | L15: =H15*J15 -> 0
A16: 5 | C16: =IFERROR(VLOOKUP(B16,Stock,3,FALSE),"") | L16: =H16*J16 -> 0
A17: 6 | C17: =IFERROR(VLOOKUP(B17,Stock,3,FALSE),"") | L17: =H17*J17 -> 0
A18: BCA 5781177611 an Adrian Kurniawan | K18: TOTAL | L18: =SUM(L12:L17) -> 5330000
K19: DP | L19: 0
E20: Kaca yang sudah dipesan/dipasang tidak dapat dibatalkan/dikembalikan. Tidak ada garansi kaca. | K20: DISKON | L20: 0
K21: NETTO | L21: =L18-L19-L20 -> 5330000
K23: Ket
A24: Trust the Experts, Drive Safer and Clearer

Sheet Copy of INV VIRTUAL AMEL 2 1
A1: SENTRA AUTOGLASS TANGERANG | J1: Tanggal | L1: 46132
A2: Ruko Permata Niaga II No. 17, Taman Royal I, Tanah Tinggi, Kota Tangerang 15119 | J2: Kepada Yth.
A3: (+62) 81288009878 | (+62) 81281161200
J4: +62 858-1000-8154
J5: Tangerang
D8: NOTA PENJUALAN
A10: INV | B10: D260129 | J10: NO POL
A11: No | B11: Kode | C11: Nama Barang | H11: Qty | J11: Harga Satuan | L11: Jumlah
A12: 1 | B12: LFW-VOXY17XYG | C12: =IFERROR(VLOOKUP(B12,Stock,3,FALSE),"") -> Toyota Voxy 17- | H12: 1 | I12: PC | J12: 3326000 | L12: =H12*J12 -> 3326000
A13: 2 | B13: FDL-VOXY17AGC | C13: =IFERROR(VLOOKUP(B13,Stock,3,FALSE),"") | H13: 1 | I13: x | J13: 2004000 | L13: =H13*J13 -> 2004000
A14: 3 | C14: =IFERROR(VLOOKUP(B14,Stock,3,FALSE),"") | L14: =H14*J14 -> 0
A15: 4 | C15: =IFERROR(VLOOKUP(B15,Stock,3,FALSE),"") | L15: =H15*J15 -> 0
A16: 5 | C16: =IFERROR(VLOOKUP(B16,Stock,3,FALSE),"") | L16: =H16*J16 -> 0
A17: 6 | C17: =IFERROR(VLOOKUP(B17,Stock,3,FALSE),"") | L17: =H17*J17 -> 0
A18: BCA 5781177611 an Adrian Kurniawan | K18: TOTAL | L18: =SUM(L12:L17) -> 5330000
K19: DP | L19: 0
E20: Kaca yang sudah dipesan/dipasang tidak dapat dibatalkan/dikembalikan. Tidak ada garansi kaca. | K20: DISKON | L20: 0
K21: NETTO | L21: =L18-L19-L20 -> 5330000
K23: Ket
A24: Trust the Experts, Drive Safer and Clearer

Sheet tanda terima dp
A1: Tanda Terima Pembayaran
A4: NO | B4: PENJUALAN | C4: NOMINAL
A5: 1 | B5: Tanda Jadi D260113 TRW-VIOS02XYG | C5: 100000
B9: TOTAL | C9: =SUM(C5:C8) -> 100000
B11: Tangerang, 18 April 2026
A13: Trust the Experts, Drive Safer and Clearer

Sheet Copy of INV VIRTUAL AMEL 2
A1: SENTRA AUTOGLASS TANGERANG | J1: Tanggal | L1: 46130
A2: Ruko Permata Niaga II No. 17, Taman Royal I, Tanah Tinggi, Kota Tangerang 15119 | J2: Kepada Yth.
A3: (+62) 81288009878 | (+62) 81281161200 | J3: Iko/Reza
J4: +62 822-2937-5656
J5: Tangerang
D8: NOTA PENJUALAN
A10: INV | B10: D260115 | J10: NO POL
A11: No | B11: Kode | C11: Nama Barang | H11: Qty | J11: Harga Satuan | L11: Jumlah
A12: 1 | B12: LFW-QUESTERXYG | C12: =IFERROR(VLOOKUP(B12,Stock,3,FALSE),"") -> Nissan Quester / Cw445 Quon 05- | H12: 2 | I12: PC | J12: 2469000 | L12: =H12*J12 -> 4938000
A13: 2 | B13: LFW-AXORXYG | C13: =IFERROR(VLOOKUP(B13,Stock,3,FALSE),"") -> Mers-Benz Axor 98- Truck | H13: 1 | I13: PC | J13: 2199000 | L13: =H13*J13 -> 2199000
A14: 3 | B14: OTH-SERTRANSPORT | C14: =IFERROR(VLOOKUP(B14,Stock,3,FALSE),"") -> Transport | H14: 1 | I14: x | J14: 1100000 | L14: =H14*J14 -> 1100000
A15: 4 | C15: =IFERROR(VLOOKUP(B15,Stock,3,FALSE),"") | L15: =H15*J15 -> 0
A16: 5 | C16: =IFERROR(VLOOKUP(B16,Stock,3,FALSE),"") | L16: =H16*J16 -> 0
A17: 6 | C17: =IFERROR(VLOOKUP(B17,Stock,3,FALSE),"") | L17: =H17*J17 -> 0
A18: BCA 5781177611 an Adrian Kurniawan | K18: TOTAL | L18: =SUM(L12:L17) -> 8237000
K19: DP | L19: 3000000
E20: Kaca yang sudah dipesan/dipasang tidak dapat dibatalkan/dikembalikan. Tidak ada garansi kaca. | K20: DISKON | L20: 0
K21: NETTO | L21: =L18-L19-L20 -> 5237000
K23: Ket
A24: Trust the Experts, Drive Safer and Clearer

Sheet INV SALSA
A1: SENTRA AUTOGLASS TANGERANG | J1: Tanggal | L1: 46139
A2: Ruko Permata Niaga II No. 17, Taman Royal I, Tanah Tinggi, Kota Tangerang 15119 | J2: Kepada Yth.
A3: (+62) 81288009878 | (+62) 81281161200 | J3: Melissa
J4: +62 813-8605-9107
D8: NOTA PENJUALAN
A10: INV | B10: D260167 | J10: NO POL
A11: No | B11: Kode | C11: Nama Barang | H11: Qty | J11: Harga Satuan | L11: Jumlah
A12: 1 | B12: TRW-INNOVA15XYG | C12: =IFERROR(VLOOKUP(B12,Stock,3,FALSE),"") -> Toyota Innova 15- 2nd Gen | H12: 1 | I12: PC | J12: 1199000 | L12: =H12*J12 -> 1199000
A13: 2 | B13: OTH-SERTRANSPORT | C13: =IFERROR(VLOOKUP(B13,Stock,3,FALSE),"") -> Transport | H13: 1 | I13: X | J13: 100000 | L13: =H13*J13 -> 100000
A14: 3 | C14: =IFERROR(VLOOKUP(B14,Stock,3,FALSE),"") | L14: =H14*J14 -> 0
A15: 4 | C15: =IFERROR(VLOOKUP(B15,Stock,3,FALSE),"") | L15: =H15*J15 -> 0
A16: 5 | C16: =IFERROR(VLOOKUP(B16,Stock,3,FALSE),"") | L16: =H16*J16 -> 0
A17: 6 | C17: =IFERROR(VLOOKUP(B17,Stock,3,FALSE),"") | L17: =H17*J17 -> 0
A18: BCA 5781177611 an Adrian Kurniawan | K18: TOTAL | L18: =SUM(L12:L17) -> 1299000
K19: DP | L19: 100000
E20: Kaca yang sudah dipesan/dipasang tidak dapat dibatalkan/dikembalikan. Tidak ada garansi kaca. | K20: DISKON | L20: 0
K21: NETTO | L21: =L18-L19-L20 -> 1199000
K23: Ket
A24: Trust the Experts, Drive Safer and Clearer

Sheet Copy of INV SALSA
A1: SENTRA AUTOGLASS TANGERANG | J1: Tanggal | L1: 46137
A2: Ruko Permata Niaga II No. 17, Taman Royal I, Tanah Tinggi, Kota Tangerang 15119 | J2: Kepada Yth.
A3: (+62) 81288009878 | (+62) 81281161200 | J3: Satria Dwi Kusuma
J4: 62 812-8771-8773
D8: NOTA PENJUALAN
A10: INV | B10: D260164 | J10: NO POL | L10: B 1189 JFW
A11: No | B11: Kode | C11: Nama Barang | H11: Qty | J11: Harga Satuan | L11: Jumlah
A12: 1 | B12: RDL-BRV22ASH | C12: Honda BR-V 22- 2nd Gen | H12: 1 | I12: PC | J12: 650000 | L12: =H12*J12 -> 650000
A13: 2 | B13: FILM-60STD | C13: Automotive Film Standard - Black 60% | H13: 1 | I13: PC | J13: 200000 | L13: =H13*J13 -> 200000
A14: 3 | B14: OTH-SERTRANSPORT | C14: =IFERROR(VLOOKUP(B14,Stock,3,FALSE),"") -> Transport | H14: 1 | I14: X | J14: 75000 | L14: =H14*J14 -> 75000
A15: 4 | C15: =IFERROR(VLOOKUP(B15,Stock,3,FALSE),"") | L15: =H15*J15 -> 0
A16: 5 | C16: =IFERROR(VLOOKUP(B16,Stock,3,FALSE),"") | L16: =H16*J16 -> 0
A17: 6 | C17: =IFERROR(VLOOKUP(B17,Stock,3,FALSE),"") | L17: =H17*J17 -> 0
A18: BCA 5781177611 an Adrian Kurniawan | K18: TOTAL | L18: =SUM(L12:L17) -> 925000
K19: DP | L19: 100000
E20: Kaca yang sudah dipesan/dipasang tidak dapat dibatalkan/dikembalikan. Tidak ada garansi kaca. | K20: DISKON | L20: 0
K21: NETTO | L21: =L18-L19-L20 -> 825000
K23: Ket
A24: Trust the Experts, Drive Safer and Clearer

Sheet INV VIRTUAL VISCA
A1: SENTRA AUTOGLASS TANGERANG | J1: Tanggal | L1: 46118
A2: Ruko Permata Niaga II No. 17, Taman Royal I, Tanah Tinggi, Kota Tangerang 15119 | J2: Kepada Yth.
A3: (+62) 81288009878 | (+62) 81281161200
D8: NOTA PENJUALAN
A10: INV | B10: D260116 | J10: NO POL
A11: No | B11: Kode | C11: Nama Barang | H11: Qty | J11: Harga Satuan | L11: Jumlah
A12: 1 | C12: =IFERROR(VLOOKUP(B12,Stock,3,FALSE),"") | H12: 1 | I12: PC | L12: =H12*J12 -> 0
A13: 2 | C13: =IFERROR(VLOOKUP(B13,Stock,3,FALSE),"") | L13: =H13*J13 -> 0
A14: 3 | C14: =IFERROR(VLOOKUP(B14,Stock,3,FALSE),"") | L14: =H14*J14 -> 0
A15: 4 | C15: =IFERROR(VLOOKUP(B15,Stock,3,FALSE),"") | L15: =H15*J15 -> 0
A16: 5 | L16: =H16*J16 -> 0
A17: 6
A18: BCA 5781177611 an Adrian Kurniawan | K18: TOTAL | L18: =SUM(L12:L17) -> 0
A19: Hormat Kami, | K19: DP | L19: 0 | P19: ='Current Stock'!O1414
E20: Kaca yang sudah dipesan/dipasang tidak dapat dibatalkan/dikembalikan. Tidak ada garansi kaca. | K20: DISKON | L20: 0
K21: NETTO | L21: =L18-L19-L20 -> 0
K23: Ket
B26: Visca

Sheet Copy of INV VIRTUAL VISCA
A1: SENTRA AUTOGLASS TANGERANG | J1: Tanggal | L1: 46137
A2: Ruko Permata Niaga II No. 17, Taman Royal I, Tanah Tinggi, Kota Tangerang 15119 | J2: Kepada Yth.
A3: (+62) 81288009878 | (+62) 81281161200 | J3: Mulya
J4: +62 858-1004-5727
D8: NOTA PENJUALAN
A10: INV | B10: D260159 | J10: NO POL
A11: No | B11: Kode | C11: Nama Barang | H11: Qty | J11: Harga Satuan | L11: Jumlah
A12: 1 | B12: RDL-SIENTAAGC | C12: Toyota Sienta 15- | H12: 1 | I12: PC | J12: 985000 | L12: =H12*J12 -> 985000
A13: 2 | C13: =IFERROR(VLOOKUP(B13,Stock,3,FALSE),"") | L13: =H13*J13 -> 0
A14: 3 | C14: =IFERROR(VLOOKUP(B14,Stock,3,FALSE),"") | L14: =H14*J14 -> 0
A15: 4 | L15: =H15*J15 -> 0
A16: 5 | L16: =H16*J16 -> 0
A17: 6 | L17: 0
A18: BCA 5781177611 an Adrian Kurniawan | K18: TOTAL | L18: =SUM(L12:L17) -> 985000
K19: DP | L19: 492500
E20: Kaca yang sudah dipesan/dipasang tidak dapat dibatalkan/dikembalikan. Tidak ada garansi kaca. | K20: DISKON | L20: 0
K21: NETTO | L21: =L18-L19-L20 -> 492500
K23: Ket
A24: Trust the Experts, Drive Safer and Clearer | K24: DP 50%

Sheet Copy of Copy of INV VIRTUAL VIS
A1: SENTRA AUTOGLASS TANGERANG | J1: Tanggal | L1: 46134
A2: Ruko Permata Niaga II No. 17, Taman Royal I, Tanah Tinggi, Kota Tangerang 15119 | J2: Kepada Yth.
A3: (+62) 81288009878 | (+62) 81281161200 | J3: Pak Arief
J4: +62 812-8278-6940
D8: NOTA PENJUALAN
A10: INV | B10: D260149 | J10: NO POL | L10: B 2181 VVO
A11: No | B11: Kode | C11: Nama Barang | H11: Qty | J11: Harga Satuan | L11: Jumlah
A12: 1 | B12: FILM-BPSG | C12: =IFERROR(VLOOKUP(B12,Stock,3,FALSE),"") -> Black Phantom Solar Gard | H12: 1 | I12: PC | J12: 1375000 | L12: =H12*J12 -> 1375000
A13: 2 | C13: =IFERROR(VLOOKUP(B13,Stock,3,FALSE),"") | L13: =H13*J13 -> 0
A14: 3 | C14: =IFERROR(VLOOKUP(B14,Stock,3,FALSE),"") | L14: =H14*J14 -> 0
A15: 4 | L15: =H15*J15 -> 0
A16: 5 | L16: =H16*J16 -> 0
A17: 6 | L17: 0
A18: BCA 5781177611 an Adrian Kurniawan | K18: TOTAL | L18: =SUM(L12:L17) -> 1375000
K19: DP | L19: 100000
E20: Kaca yang sudah dipesan/dipasang tidak dapat dibatalkan/dikembalikan. Tidak ada garansi kaca. | K20: DISKON | L20: 0
K21: NETTO | L21: =L18-L19-L20 -> 1275000
K23: Ket
A24: Trust the Experts, Drive Safer and Clearer

Sheet INV VIRTUAL VISCA 2
A1: SENTRA AUTOGLASS TANGERANG | J1: Tanggal | L1: 46133
A2: Ruko Permata Niaga II No. 17, Taman Royal I, Tanah Tinggi, Kota Tangerang 15119 | J2: Kepada Yth.
A3: (+62) 81288009878 | (+62) 81281161200 | J3: yoga
J4: +62 857-1536-2263
D8: NOTA PENJUALAN
A10: INV | B10: D260148 | J10: NO POL | L10: B 2127 TJB
A11: No | B11: Kode | C11: Nama Barang | H11: Qty | J11: Harga Satuan | L11: Jumlah
A12: 1 | B12: LFW-SANTAFE21RS2XYG | C12: Hyundai santa Fe 18-23 (thn 21-23) (2 Sensor / /\ O) | H12: 1 | I12: PC | J12: 3800000 | L12: =H12*J12 -> 3800000
A13: 2 | B13: FILM-40STD | C13: =IFERROR(VLOOKUP(B13,Stock,3,FALSE),"") -> Automotive Film Standard - Black 40% | H13: 1 | I13: PC | J13: 450000 | L13: =H13*J13 -> 450000
A14: 3 | C14: =IFERROR(VLOOKUP(B14,Stock,3,FALSE),"") | L14: =H14*J14 -> 0
A15: 4 | L15: =H15*J15 -> 0
A16: 5 | L16: =H16*J16 -> 0
A17: 6 | L17: =H17*J17 -> 0
A18: BCA 5781177611 an Adrian Kurniawan | K18: TOTAL | L18: =SUM(L12:L17) -> 4250000
K19: DP | L19: 100000
E20: Kaca yang sudah dipesan/dipasang tidak dapat dibatalkan/dikembalikan. Tidak ada garansi kaca. | K20: DISKON | L20: 0
K21: NETTO | L21: =L18-L19-L20 -> 4150000
K23: Ket
A24: Trust the Experts, Drive Safer and Clearer

Sheet Copy of INV VIRTUAL 5
J1: Tanggal | L1: 46078
A2: Ruko Permata Niaga II No. 17, Taman Royal I, Tanah Tinggi, Kota Tangerang 15119 | J2: Kepada Yth.
A3: (+62) 81288009878 | (+62) 81281161200 | J3: dikki
J4: +62 819-3813-788;
D7: INVOICE PENJUALAN
A9: INV | B9: B260136 | J9: NO POL | L9: B 1544 BOS
A10: No | B10: Kode | C10: Nama Barang | H10: Qty | J10: Harga Satuan | L10: Jumlah
A11: 1 | B11: TRW-ALPHARD15BLACKXYG | C11: =IFERROR(VLOOKUP(B11,Stock,3,FALSE),"") -> Toyota Alphard 15-17 ANH30 3rd Gen (Hitam) | H11: 1 | I11: PC | J11: 2820000 | L11: =H11*J11 -> 2820000
A12: 2 | B12: OTH-SERTRANSPORT | C12: =IFERROR(VLOOKUP(B12,Stock,3,FALSE),"") -> Transport | H12: 1 | I12: X | J12: 150000 | L12: =H12*J12 -> 150000
A13: 3 | C13: =IFERROR(VLOOKUP(B13,Stock,3,FALSE),"") | L13: =H13*J13 -> 0
A14: 4 | C14: =IFERROR(VLOOKUP(B14,Stock,3,FALSE),"") | L14: =H14*J14 -> 0
A15: 5 | C15: =IFERROR(VLOOKUP(B15,Stock,3,FALSE),"") | L15: =H15*J15 -> 0
A16: 6 | C16: =IFERROR(VLOOKUP(B16,Stock,3,FALSE),"") | L16: =H16*J16 -> 0
A17: BCA 5781177611 an Adrian Kurniawan | K17: TOTAL | L17: =SUM(L11:L16) -> 2970000
E18: Kaca yang sudah dipesan/dipasang tidak dapat dibatalkan/dikembalikan. | K18: DISKON | L18: =SUM(L12:L17) -> 3120000
K19: DP | L19: 100000
K20: DISKON | L20: 0
K21: SISA | L21: =L17-L19-L20 -> 2870000
A23: Trust the Experts, Drive Safer and Clearer | K23: Ket

Sheet INV-Asep Saipul Milah
A1: SENTRA AUTOGLASS TANGERANG | J1: Tanggal | L1: 46085
A2: Ruko Permata Niaga II No. 17, Taman Royal I, Tanah Tinggi, Kota Tangerang 15119 | J2: Kepada Yth.
A3: (+62) 81288009878 | (+62) 81281161200 | J3: Asep Saipul Milah
J4: +62 857-2121-1537
J5: Tangerang
D8: NOTA PENJUALAN
A10: INV | B10: C260017 | J10: NO POL | L10: B 2028 VVI
A11: No | B11: Kode | C11: Nama Barang | H11: Qty | J11: Harga Satuan | L11: Jumlah
A12: 1 | B12: LFW-AVANZA16XYG | C12: =IFERROR(VLOOKUP(B12,Stock,3,FALSE),"") -> Toyota Avanza / Xenia 15-21 3rd Gen | H12: 1 | I12: PC | J12: 999000 | L12: =H12*J12 -> 999000
A13: 2 | B13: FILM-40STD | C13: =IFERROR(VLOOKUP(B13,Stock,3,FALSE),"") -> Automotive Film Standard - Black 40% | H13: 1 | I13: PC | J13: 350000 | L13: =H13*J13 -> 350000
C14: =IFERROR(VLOOKUP(B14,Stock,3,FALSE),"") | L14: =H14*J14 -> 0
C15: =IFERROR(VLOOKUP(B15,Stock,3,FALSE),"") | L15: =H15*J15 -> 0
L16: =H16*J16 -> 0
A18: BCA 5781177611 an Adrian Kurniawan | K18: TOTAL | L18: =SUM(L12:L17) -> 1349000
K19: DP | L19: 0
K20: DISKON | L20: 0
K21: NETTO | L21: =L18-L19-L20 -> 1349000
K23: Ket
A24: Trust the Experts, Drive Safer and Clearer

Sheet Copy of PROFORMA INVOICE
A1: SENTRA AUTOGLASS TANGERANG | J1: Tanggal | L1: 46080
A2: Ruko Permata Niaga II No. 17, Taman Royal I, Tanah Tinggi, Kota Tangerang 15119 | J2: Kepada Yth.
A3: (+62) 81288009878 | (+62) 81281161200 | J3: Plaza Subaru Kebon Jeruk
J4: (Plaza Auto Cipta)
J5: Jakarta
D8: PROFORMA INVOICE
A10: PI | B10: TGRB01888 | J10: NO POL | L10: -
A11: No | B11: Kode | C11: Nama Barang | H11: Qty | J11: Harga Satuan | L11: Jumlah
A12: 1 | B12: LFW-FORESTER22RS3AGC | C12: =IFERROR(VLOOKUP(B12,Stock,3,FALSE),"") -> Subaru Forester 22- (3 Sensor / /\ [] /\ ) (Subaru) | H12: 1 | I12: PC | J12: 32500000 | L12: =H12*J12 -> 32500000
B13: Windshield / Kaca Depan Subaru Forester 2.0i-S EyeSight AWD CVT 2024 JF1SK7KL5RG212291 | L13: =H13*J13 -> 0
L14: =H14*J14 -> 0
L15: =H15*J15 -> 0
L16: =H16*J16 -> 0
L17: 0
A18: Pembayaran : BCA 5781177611 an Adrian Kurniawan | K18: TOTAL | L18: 32500000
K19: DISKON | L19: 550000
A20: Keterangan | K20: NETTO | L20: =L18-L19 -> 31950000
A21: - Produk yang ditawarkan merupakan Genuine / Original Automotive Glass berlogo resmi, disesuaikan berdasarkan VIN kendaraan untuk memastikan kesesuaian part. - Validitas penawaran berlaku selama 7 (tujuh) hari sejak tanggal surat ini diterbitkan. - Metode Pembayaran : Tunai
J25: Trust the Experts, Drive Safer and Clearer

Sheet JADWAL
A1: Periode 1–7 Maret
A2: Nama | B2: Fokus Mingguan | C2: Tanggung Jawab Utama | D2: 1 | E2: 2 | F2: 3 | G2: 4 | H2: 5 | I2: 6 | J2: 7
A3: Putri | B3: 🟢 Finance & Reporting | C3: Cash, petty cash, laporan
A4: Visca | B4: 🔵 Marketing & Customer | C4: Konten, follow up, review
A5: Amel | B5: 🟡 Operasional & Inventory | C5: Toolbox, stok, koordinasi teknisi
A7: Periode 8–14 Maret
A8: Nama | B8: Fokus Mingguan | C8: Tanggung Jawab Utama | D8: 8 | E8: 9 | F8: 10 | G8: 11 | H8: 12 | I8: 13 | J8: 14
A9: Putri | B9: 🟡 Operasional & Inventory | C9: Toolbox, stok, koordinasi teknisi
A10: Visca | B10: 🟢 Finance & Reporting | C10: Cash, petty cash, laporan
A11: Amel | B11: 🔵 Marketing & Customer | C11: Konten, follow up, review
A13: Periode 15–21 Maret
A14: Nama | B14: Fokus Mingguan | C14: Tanggung Jawab Utama | D14: 15 | E14: 16 | F14: 17 | G14: 18 | H14: 19 | I14: 20 | J14: 21
A15: Putri | B15: 🔵 Marketing & Customer | C15: Konten, follow up, review
A16: Visca | B16: 🟡 Operasional & Inventory | C16: Toolbox, stok, koordinasi teknisi
A17: Amel | B17: 🟢 Finance & Reporting | C17: Cash, petty cash, laporan
A19: Periode 25-31 Maret
A20: Nama | B20: Fokus Mingguan | C20: Tanggung Jawab Utama | D20: 1 | E20: 2 | F20: 3 | G20: 4 | H20: 5 | I20: 6 | J20: 7
A21: Putri | B21: 🟢 Finance & Reporting | C21: Cash, petty cash, laporan
A22: Visca | B22: 🔵 Marketing & Customer | C22: Konten, follow up, review
A23: Amel | B23: 🟡 Operasional & Inventory | C23: Toolbox, stok, koordinasi teknisi
A27: Job Desc Tiap Role | B27: Tanggung Jawab | C27: Laporan | D27: Kontrol
A28: 🟢 Finance | B28: 💰 Cash & Keuangan - Terima uang cash dari customer - Input petty cash - Cocokkan total nota vs uang masuk - Simpan uang di dompet kas dengan rapi | C28: - Buat laporan penjualan harian - Buat laporan pembelian barang - Kirim laporan ke atasan sebelum tutup - Setor uang kasir | D28: - Pastikan tidak ada nota yang belum masuk sistem - Pastikan selisih kas = 0
A29: 🟡 Operasional & Inventory | B29: 📦 Inventory - Cek toolbox dengan teknisi setiap pagi/sore - Catat pengambilan inventory - Pastikan stok fast moving aman - Laporkan jika ada stok menipis - Selalu paling update posisi tim dan kondisi tim - Membuat SJ dan input barang datang/keluar - Pengecekan barang masuk/keluar - Pastikan barang pembelian sesuai fisik - Cek dokumentasi pemasangan (before-after) - Pengecekan SPK | C29: 🔧 Koordinasi Teknis - Update kebutuhan teknisi - Update tugas teknisi
A30: 🔵 Marketing & Customer | B30: 📱 Konten & Sosial Media - Upload story WA status setiap hari - Upload story Instagram setiap hari - Posting kegiatan cabang 💬 Customer - Follow up customer pending - Balas DM dan chat (PIC Utama) - Ingatkan customer untuk kasih review | C30: ⭐ Review Target Rekap review harian Pastikan tidak ada hari kosong tanpa review

Sheet Petty Cash
A1: 1 | K1: POS KAS
A2: NO | B2: Tanggal | C2: Nama | D2: Ket | E2: Debit | F2: Kredit | G2: Sisa | H2: Input by | I2: Terima uang | J2: Cek | K2: Transportasi | L2: Perlengkapan Workshop | M2: Administrasi & Kantor , Inventory | N2: Konsumsi | O2: Perawatan Fasilitas | P2: Biaya Tak terduga
A3: 1 | B3: 45913 | C3: Uang Masuk | E3: 500000 | G3: =E3-F3 -> 500000 | H3: CICI | I3: THARINA | J3: CICI
A4: 2 | B4: 45913 | C4: Perlengkapan Workshop - TB SURYA | D4: Paku 3kg | F4: 48000 | G4: =G3+E4-F4 -> 452000 | H4: Tharina | I4: ko Rian | L4: 48000
A5: 3 | B5: 45918 | C5: Perlengkapan Workshop - Lucky Seven | D5: Galon atas | F5: 6000 | G5: =G4+E5-F5 -> 446000 | H5: Tharina | I5: Guntur | N5: 6000
A6: 4 | B6: 45918 | C6: Perlengkapan Workshop - Yupiter | D6: Galon bawah | F6: 20000 | G6: =G5+E6-F6 -> 426000 | H6: Tharina | I6: Guntur | N6: 20000
A7: 5 | B7: 45923 | C7: Parkir saat home service | D7: 2 lokasi (Rp 5.000 dan Rp 4.000) | F7: 9000 | G7: =G6+E7-F7 -> 417000 | H7: Tharina | I7: Pavel | K7: 9000
A8: 6 | B8: 45923 | C8: Perlengkapan workshop - Indomaret | D8: Shampoo | F8: 17900 | G8: =G7+E8-F8 -> 399100 | H8: Tharina | I8: Pavel | O8: 17900
A9: 7 | B9: 45923 | C9: Perlengkapan workshop - Indomaret | D9: Sabun | F9: 19000 | G9: =G8+E9-F9 -> 380100 | H9: Tharina | I9: Pavel | O9: 19000
A10: 8 | B10: 45924 | C10: Perlengkapan workshop - Mobil | D10: Bensin | F10: 300000 | G10: =G9+E10-F10 -> 80100 | H10: Tharina | I10: Guntur | K10: 300000
A11: 9 | B11: 45924 | C11: Uang masuk | E11: 500000 | G11: =G10+E11-F11 -> 580100 | H11: Tharina | I11: Tharina
A12: 10 | B12: 45924 | C12: Gojek send | D12: LMB ke TGR | F12: 30000 | G12: =G11+E12-F12 -> 550100 | H12: Tharina | I12: Gojek | K12: 30000
A13: 11 | B13: 45924 | C13: Gocar send | D13: BGI ke TGR | F13: 32000 | G13: =G12+E13-F13 -> 518100 | H13: Tharina | I13: Gocar | K13: 32000
A14: 12 | B14: 45924 | C14: Perlengkapan workshop - Talago | D14: HVS 1 rim | F14: 52000 | G14: =G13+E14-F14 -> 466100 | H14: Tharina | I14: Yansyah | M14: 52000
A15: 13 | B15: 45925 | C15: Perlengkapan workshop - Motor | D15: Bensin | F15: 70000 | G15: =G14+E15-F15 -> 396100 | H15: Tharina | I15: Yansyah | K15: 70000
A16: 14 | B16: 45925 | C16: Perlengkapan Workshop - Lucky Seven | D16: Galon bawah | F16: 6000 | G16: =G15+E16-F16 -> 390100 | H16: Tharina | I16: Guntur | N16: 6000
A17: 15 | B17: 45925 | C17: Perlengkapan workshop - Mobil | D17: LMB ke TGR | F17: 51000 | G17: =G16+E17-F17 -> 339100 | H17: Tharina | I17: Gocar | K17: 51000
A18: 16 | B18: 45926 | C18: Perlengkapan workshop - Motor | D18: Benerin rante | F18: 10000 | G18: =G17+E18-F18 -> 329100 | H18: Tharina | I18: Agung | P18: 10000
A19: 17 | B19: 45926 | C19: Gocar send | D19: BGI ke TGR | F19: 35000 | G19: =G18+E19-F19 -> 294100 | H19: Tharina | I19: Gocar | K19: 35000
A20: 18 | B20: 45927 | C20: Perlengkapan workshop - Mobil | D20: Bensin | F20: 290000 | G20: =G19+E20-F20 -> 4100 | H20: Tharina | I20: Gocar | K20: 290000
A21: 19 | B21: 45929 | C21: Uang masuk | E21: 500000 | G21: =G20+E21-F21 -> 504100 | H21: Tharina | I21: Tharina
A22: 20 | B22: 45929 | C22: Perlengkapan Workshop - Indomaret | D22: Prostek | F22: 19400 | G22: =G21+E22-F22 -> 484700 | H22: Tharina | I22: Pavel | O22: 19400
A23: 21 | B23: 45931 | C23: Gojek send | D23: MOS ke TGR | F23: 68000 | G23: =G22+E23-F23 -> 416700 | H23: Tharina | I23: ko Rian | K23: 68000
A24: 22 | B24: 45931 | C24: Gojek send | D24: LMB ke TGR | F24: 32500 | G24: =G23+E24-F24 -> 384200 | H24: Tharina | I24: Gojek | K24: 32500
A25: 23 | B25: 45931 | C25: Gocar send | D25: LMB ke TGR | F25: 52000 | G25: =G24+E25-F25 -> 332200 | H25: Tharina | I25: Gocar | K25: 52000
A26: 24 | B26: 45932 | C26: Perlengkapan workshop - Indomaret | D26: Galon | F26: 42000 | G26: =G25+E26-F26 -> 290200 | H26: Tharina | I26: ko Rian | N26: 42000
A27: 25 | B27: 45933 | C27: Gojek send | D27: TGR ke BKS | F27: 120000 | G27: =G26+E27-F27 -> 170200 | H27: Tharina | I27: Ko Rian | K27: 120000
A28: 26 | B28: 45933 | C28: Perlengkapan workshop - Motor | D28: Bensin | F28: 100000 | G28: =G27+E28-F28 -> 70200 | H28: Tharina | I28: Ko Rian | K28: 100000
A29: 27 | B29: 45933 | C29: Gojek send | D29: LMB ke TGR | F29: 33000 | G29: =G28+E29-F29 -> 37200 | H29: Tharina | I29: Ko Rian | K29: 33000
A30: 28 | B30: 45934 | C30: Uang masuk | E30: 800000 | G30: =G29+E30-F30 -> 837200 | H30: Tharina | I30: Tharina | J30: CICI
A31: 29 | B31: 45934 | C31: Perlengkapan workshop - Epoxy | D31: TB Surya | F31: 20000 | G31: =G30+E31-F31 -> 817200 | H31: Tharina | I31: Agung | L31: 20000
A32: 30 | B32: 45934 | C32: Perlengkapan workshop - Mobil | D32: Bensin | F32: 300000 | G32: =G31+E32-F32 -> 517200 | H32: Tharina | I32: Ko Rian | K32: 300000
A33: 31 | B33: 45934 | C33: Perlengkapan Workshop - Lucky Seven | D33: Galon bawah | F33: 7000 | G33: =G32+E33-F33 -> 510200 | H33: Tharina | I33: Guntur | N33: 7000
A34: 32 | B34: 45936 | C34: Perlengkapan workshop - Mobil | D34: Bensin | F34: 300000 | G34: =G33+E34-F34 -> 210200 | H34: Ko Rian | I34: Guntur | K34: 300000
A35: 33 | B35: 45936 | C35: Lalamove Van Kaca Evalia | D35: MOS ke TGR | F35: 125000 | G35: =G34+E35-F35 -> 85200 | H35: Ko Rian | I35: Guntur | K35: 125000
A36: 34 | B36: 45939 | C36: Uang Masuk | E36: 500000 | G36: =G35+E36-F36 -> 585200 | H36: Cici | I36: Ko Rian
A37: 35 | B37: 45939 | C37: Perlengkapan workshop - Mobil | D37: E-toll | F37: 200000 | G37: =G36+E37-F37 -> 385200 | H37: Ko Rian | I37: Ko Rian | K37: 300000
A38: 36 | B38: 45939 | C38: Perlengkapan workshop - Mobil | D38: Bensin | F38: 300000 | G38: =G37+E38-F38 -> 85200 | H38: Ko Rian | I38: Ko Rian | K38: 200000
A39: 37 | B39: 45940 | C39: Perlengkapan Workshop - Lucky Seven | D39: Galon atas | F39: 20000 | G39: =G38+E39-F39 -> 65200 | H39: Ko Rian | I39: Guntur | N39: 20000
A40: 38 | B40: 45941 | C40: Uang Masuk | E40: 1000000 | G40: =G39+E40-F40 -> 1065200 | H40: Ko rian | I40: ko rian
...

Sheet Laporan Setor
A1: LAPORAN KAS TUNAI CABANG TANGERANG
A2: Tanggal | B2: Saldo Awal | C2: Cash Masuk | D2: Cash Keluar | E2: Setoran | F2: Saldo Akhir | G2: Selisih | H2: Setor ke | I2: Input By | J2: Diterima oleh | K2: Done setor bank
A3: 46079 | B3: 125000 | C3: 1150000 | E3: 1150000 | F3: =B3+C3-D3-E3 -> 125000 | H3: rian | I3: putri | J3: RIAN | K3: sudah trf
A4: 46079 | B4: =F3 -> 125000 | C4: 2831000 | E4: 2831000 | F4: =B4+C4-D4-E4 -> 125000 | H4: rian | I4: rian | J4: rian | K4: sudah trf
A5: 46081 | B5: =F4 -> 125000 | C5: 400000 | E5: 400000 | F5: =B5+C5-D5-E5 -> 125000 | H5: rian | I5: putri | J5: rian | K5: sudah trf
A6: 46081 | B6: =F5 -> 125000 | C6: 1050000 | E6: 1050000 | F6: =B6+C6-D6-E6 -> 125000 | H6: rian | I6: putri | J6: rian | K6: sudah trf
A7: 46081 | B7: =F6 -> 125000 | C7: 1000000 | E7: 1000000 | F7: =B7+C7-D7-E7 -> 125000 | H7: rian | I7: rian | J7: rian | K7: sudah trf
A8: 46081 | B8: =F7 -> 125000 | C8: 500000 | E8: 500000 | F8: =B8+C8-D8-E8 -> 125000 | H8: rian | I8: rian | J8: rian | K8: sudah trf
A9: 46056 | B9: =F8 -> 125000 | C9: 1500000 | E9: 1500000 | F9: =B9+C9-D9-E9 -> 125000 | H9: rian | I9: putri | J9: rian | K9: sudah trf
A10: 46056 | B10: =F9 -> 125000 | C10: 525000 | E10: 525000 | F10: =B10+C10-D10-E10 -> 125000 | H10: rian | I10: putri | J10: rian | K10: sudah trf
A11: 46084 | B11: =F10 -> 125000 | C11: 818000 | E11: 818000 | F11: =B11+C11-D11-E11 -> 125000 | H11: rian | I11: putri | J11: RIAN | K11: sudah trf
A12: 46086 | B12: =F11 -> 125000 | C12: 2492000 | E12: 2492000 | F12: =B12+C12-D12-E12 -> 125000 | H12: cici | I12: putri | J12: rian | K12: sudah trf
A13: 46086 | B13: =F12 -> 125000 | C13: 1510000 | E13: 1510000 | F13: =B13+C13-D13-E13 -> 125000 | H13: rian | I13: putri | J13: rian | K13: sudah trf
A14: 46086 | B14: =F13 -> 125000 | C14: 1800000 | E14: 1800000 | F14: =B14+C14-D14-E14 -> 125000 | H14: rian | I14: putri | J14: rian | K14: sudah trf
A15: 46087 | B15: =F14 -> 125000 | C15: 350000 | E15: 350000 | F15: =B15+C15-D15-E15 -> 125000 | H15: cici | I15: putri | J15: cici | K15: sudah trf
... A47: 46108 | B47: =F46 -> 201000 | C47: 2870000 | E47: 2900000 | F47: =B47+C47-D47-E47 -> 171000 | H47: Rian | I47: putri | J47: putri | K47: setor
A48: 46109 | B48: =F47 -> 171000 | C48: 100000 | F48: =B48+C48-D48-E48 -> 271000 | H48: Rian | I48: putri | J48: putri | K48: setor
A49: 46109 | B49: =F48 -> 271000 | C49: 1550000 | E49: 1550000 | F49: =B49+C49-D49-E49 -> 271000 | H49: cici | I49: putri | J49: Rian | K49: Sudah TRF
A50: 46111 | B50: =F49 -> 271000 | C50: 1190000 | E50: 1336000 | F50: =B50+C50-D50-E50 -> 125000 | H50: Rian | I50: visca | J50: Rian | K50: Sudah TRF
A51: 46112 | B51: =F50 -> 125000 | C51: 350000 | E51: 350000 | F51: =B51+C51-D51-E51 -> 125000 | H51: Rian | I51: visca | J51: Rian | K51: Sudah TRF
A52: 46113 | B52: =F51 -> 125000 | C52: 1000000 | E52: 1000000 | F52: =B52+C52-D52-E52 -> 125000 | H52: Rian | I52: visca | J52: Rian | K52: Sudah TRF
A53: 46114 | B53: =F52 -> 125000 | C53: 2700000 | E53: 2700000 | F53: =B53+C53-D53-E53 -> 125000 | H53: Rian | I53: visca | J53: Rian | K53: Sudah TRF
A54: 46115 | B54: =F53 -> 125000 | C54: 950000 | E54: 950000 | F54: =B54+C54-D54-E54 -> 125000 | H54: Rian | I54: visca | J54: Rian | K54: Sudah TRF
A55: 46115 | B55: =F54 -> 125000 | C55: 1150000 | E55: 1150000 | F55: =B55+C55-D55-E55 -> 125000 | H55: Rian | I55: visca | J55: Rian | K55: Sudah TRF
A56: 46118 | B56: =F55 -> 125000 | C56: 1446000 | E56: 1446000 | F56: =B56+C56-D56-E56 -> 125000 | H56: Rian | I56: visca | J56: Rian | K56: Sudah TRF
A57: 46118 | B57: =F56 -> 125000 | C57: 1200000 | E57: 1200000 | F57: =B57+C57-D57-E57 -> 125000 | H57: Rian | I57: visca | J57: Rian | K57: Sudah TRF
A58: 46120 | B58: =F57 -> 125000 | C58: 1100000 | E58: 1100000 | F58: =B58+C58-D58-E58 -> 125000 | H58: Rian | I58: visca | J58: Rian | K58: Petty Cash
A59: 46122 | B59: =F58 -> 125000 | C59: 900000 | E59: 900000 | F59: =B59+C59-D59-E59 -> 125000 | I59: visca | J59: Rian | K59: Sudah TRF
A60: 46123 | B60: =F59 -> 125000 | C60: 1000000 | E60: 1000000 | F60: =B60+C60-D60-E60 -> 125000 | J60: Rian | K60: Sudah TRF
A61: 46130 | B61: =F60 -> 125000 | C61: 1722000 | E61: 1722000 | F61: =B61+C61-D61-E61 -> 125000 | I61: visca | J61: Rian | K61: Sudah TRF
A62: 46132 | B62: =F61 -> 125000 | C62: 1200000 | E62: 1200000 | F62: =B62+C62-D62-E62 -> 125000 | H62: rian | I62: rian | J62: Rian | K62: Sudah TRF
A63: 46134 | B63: =F62 -> 125000 | C63: 1823000 | E63: 1823000 | F63: =B63+C63-D63-E63 -> 125000 | I63: visca | J63: Rian | K63: Sudah TRF
A64: 46135 | B64: =F63 -> 125000 | C64: 1650000 | E64: 1650000 | F64: =B64+C64-D64-E64 -> 125000 | I64: visca | J64: Rian | K64: Sudah TRF
A65: 46136 | B65: =F64 -> 125000 | C65: 1000000 | E65: 1000000 | F65: =B65+C65-D65-E65 -> 125000 | I65: visca | J65: Rian | K65: Sudah TRF
B66: =F65 -> 125000 | F66: =B66+C66-D66-E66 -> 125000
B67: =F66 -> 125000 | F67: =B67+C67-D67-E67 -> 125000
B68: =F67 -> 125000 | F68: =B68+C68-D68-E68 -> 125000
B69: =F68 -> 125000 | F69: =B69+C69-D69-E69 -> 125000
B70: =F69 -> 125000 | F70: =B70+C70-D70-E70 -> 125000
B71: =F70 -> 125000 | F71: =B71+C71-D71-E71 -> 125000
...

Sheet X
B1: INV | C1: SUP | D1: KODE | E1: NAMA | F1: PC | G1: Harga | H1: Total Harga | I1: Hutang | J1: Jatuh Tempo | K1: Input By | L1: Check | M1: Bayar? | N1: Tanggal | O1: Kode Sistem
A3: 45719 | B3: 2503056 | C3: BGI | D3: LFW-ALMAZRSXYG | E3: =IFERROR(VLOOKUP(D3,Stock,3,FALSE),"") -> Wuling Almaz (Sensor) | F3: 1 | G3: 1890000 | H3: =F3*G3 -> 1890000 | J3: 45778 | K3: CICI | L3: OK | M3: TF 388 | N3: 45773
A4: 45721 | B4: 2503138 | C4: BGI | D4: LFW-TIMORMU | E4: =IFERROR(VLOOKUP(D4,Stock,3,FALSE),"") -> Kia Timor 95-98 / Sephia 94-05 | F4: 1 | G4: 805000 | H4: =G4*F4 -> 805000 | I4: =H4 -> 805000 | L4: OK | M4: TF 388 | N4: 45773
A5: 45721 | B5: 2503138 | C5: BGI | D5: TRW-IGNISXYG | E5: =IFERROR(VLOOKUP(D5,Stock,3,FALSE),"") -> Suzuki Ignis 17- | F5: 1 | G5: 594300 | H5: =G5*F5 -> 594300 | I5: =H5 -> 594300 | L5: OK | M5: TF 388 | N5: 45773
A6: 45722 | B6: 2503194 | C6: BGI | D6: SWL-PAJERO08XYG | E6: =IFERROR(VLOOKUP(D6,Stock,3,FALSE),"") -> Mitsubishi Pajero 08-16 | F6: 1 | G6: 412300 | H6: =G6*F6 -> 412300 | I6: =H6 -> 412300 | L6: OK | M6: TF 388 | N6: 45773
A7: 45722 | B7: BCP2025C000019 | C7: MJD | D7: TRW-SIGRA16MU | E7: =IFERROR(VLOOKUP(D7,Stock,3,FALSE),"") -> Toyota Calya / Sigra 16- | F7: 1 | G7: 417150 | H7: =G7*F7 -> 417150 | M7: TF 388 | N7: 45724
A8: 45722 | B8: BCP2025C000019 | C8: MJD | D8: FDR-SIGRA16MU | E8: =IFERROR(VLOOKUP(D8,Stock,3,FALSE),"") -> Toyota Calya / Sigra 16- | F8: 1 | G8: 195000 | H8: =G8*F8 -> 195000 | M8: TF 388 | N8: 45724
A9: 45722 | B9: BCP2025C000019 | C9: MJD | D9: FDR-INNOVA15ASH | E9: =IFERROR(VLOOKUP(D9,Stock,3,FALSE),"") -> Toyota Innova 15- 2nd Gen | F9: 1 | G9: 440000 | H9: =G9*F9 -> 440000 | M9: TF 388 | N9: 45724
A10: 45723 | B10: 2503215 | C10: BGI | D10: LFW-AUDIB811XYG | E10: =IFERROR(VLOOKUP(D10,Stock,3,FALSE),"") -> Audi A4 08-15 B8 [11-15] (1 Sensor / O Sempurna) | F10: 1 | G10: 3276700 | H10: =G10*F10 -> 3276700 | I10: =H10 -> 3276700 | L10: OK | M10: TF 388 | N10: 45773
A11: 45723 | B11: 2503215 | C11: BGI | D11: LFW-VIOS02MU | E11: =IFERROR(VLOOKUP(D11,Stock,3,FALSE),"") -> Toyota Vios 02-07 XP40 1st Gen | F11: 1 | G11: 773500 | H11: =G11*F11 -> 773500 | I11: =H11 -> 773500 | L11: OK | M11: TF 388 | N11: 45773
A12: 45723 | B12: 2503241 | C12: BGI | D12: TRW-RUSH17HXYG | E12: =IFERROR(VLOOKUP(D12,Stock,3,FALSE),"") -> Toyota Rush / Terios 18- | F12: 1 | G12: 526400 | H12: =G12*F12 -> 526400 | I12: =H12 -> 526400 | L12: OK | M12: TF 388 | N12: 45773
A13: 45724 | B13: BCP2025C000026 | C13: MJD | D13: LFW-CRV95XYG | E13: =IFERROR(VLOOKUP(D13,Stock,3,FALSE),"") -> Honda CR-V 95-01 1st Gen | F13: 1 | G13: 984150 | H13: =G13*F13 -> 984150 | M13: TF 388 | N13: 45724
A14: 45724 | B14: BCP2025C000027 | C14: MJD | D14: OTH-LIST04TOYDAI | E14: =IFERROR(VLOOKUP(D14,Stock,3,FALSE),"") -> List Kaca Depan Code 04 | F14: 5 | G14: 65000 | H14: =G14*F14 -> 325000 | M14: TF 388 | N14: 45724
A15: 45724 | B15: BCP2025C000027 | C15: MJD | D15: OTH-LIST11TOYDAI | E15: =IFERROR(VLOOKUP(D15,Stock,3,FALSE),"") -> List Kaca Depan Code 11 | F15: 5 | G15: 65000 | H15: =G15*F15 -> 325000 | M15: TF 388 | N15: 45724
A16: 45726 | B16: BCP2025C000031 | C16: MJD | D16: LFW-HIACEXYG | E16: =IFERROR(VLOOKUP(D16,Stock,3,FALSE),"") -> Toyota Hi-Ace 04-20 Commuter | F16: 1 | G16: 951075 | H16: =G16*F16 -> 951075 | M16: TF 388 | N16: 45730
A17: 45728 | B17: BCP2025C000034 | C17: MJD | D17: TRW-SIGRA16MU | E17: =IFERROR(VLOOKUP(D17,Stock,3,FALSE),"") -> Toyota Calya / Sigra 16- | F17: 1 | G17: 417150 | H17: =G17*F17 -> 417150 | M17: TF 388 | N17: 45728
A18: 45724 | B18: AG-R2503000072 | C18: AG | D18: TRW-AVANZA21HASH | E18: =IFERROR(VLOOKUP(D18,Stock,3,FALSE),"") -> Toyota Avanza / Xenia 21- 4th Gen | F18: 1 | G18: 650000 | H18: =G18*F18 -> 650000 | M18: TF 388 | N18: 45735
A19: 45729 | B19: SI2025C000114 | C19: MJD | D19: LFW-CROSSXYG | E19: =IFERROR(VLOOKUP(D19,Stock,3,FALSE),"") -> Toyota Corolla Cross 21- | F19: 1 | G19: 2058750 | H19: =G19*F19 -> 2058750 | M19: TF 388 | N19: 45735
A20: 45726 | B20: 2503267 | C20: BGI | D20: TRW-BRIONOLBGXYG | E20: =IFERROR(VLOOKUP(D20,Stock,3,FALSE),"") -> Honda Brio 10-17 [Tanpa Lubang] | F20: 1 | G20: 668500 | H20: =G20*F20 -> 668500 | L20: OK | M20: TF 388 | N20: 45784
A21: 45726 | B21: 2503267 | C21: BGI | D21: LFW-BIANTEXYG | E21: =IFERROR(VLOOKUP(D21,Stock,3,FALSE),"") -> Mazda Biante 08- | F21: 1 | G21: 2317700 | H21: =G21*F21 -> 2317700 | L21: OK | M21: TF 388 | N21: 45784
A22: 45726 | B22: 2503300 | C22: BGI | D22: LFW-COROLLA91XYG | E22: =IFERROR(VLOOKUP(D22,Stock,3,FALSE),"") -> Toyota Corolla Great E100 91-96 7th Gen | F22: 1 | G22: 986300 | H22: =G22*F22 -> 986300 | L22: OK | M22: TF 388 | N22: 45773
A23: 45727 | B23: 2503323 | C23: BGI | D23: TRW-BALENO15XYG | E23: =IFERROR(VLOOKUP(D23,Stock,3,FALSE),"") -> Suzuki Baleno 15-21 | F23: 1 | G23: 744800 | H23: =G23*F23 -> 744800 | L23: OK | M23: TF 388 | N23: 45784
A24: 45727 | B24: 2503323 | C24: BGI | D24: OTH-PETIKAYU | E24: =IFERROR(VLOOKUP(D24,Stock,3,FALSE),"") -> Peti Kayu | F24: 1 | G24: 150000 | H24: =G24*F24 -> 150000 | L24: OK | M24: TF 388 | N24: 45784
A25: 45727 | B25: 2503328 | C25: BGI | D25: LFW-FORTUNER15MU | E25: =IFERROR(VLOOKUP(D25,Stock,3,FALSE),"") -> Toyota Fortuner 15- 2nd Gen | F25: 1 | G25: 1015000 | H25: =G25*F25 -> 1015000 | L25: OK | M25: TF 388 | N25: 45784
C26: BKS | D26: LFW-GRANMAXMU | E26: =IFERROR(VLOOKUP(D26,Stock,3,FALSE),"") -> Daihatsu Gran Max / Luxio 07- | F26: 1 | H26: =G26*F26 -> 0
A27: 45728 | B27: 2503372 | C27: BGI | D27: LFW-OUTLANDERXYG | E27: =IFERROR(VLOOKUP(D27,Stock,3,FALSE),"") -> Mitsubishi Outlander 10-21 GA3 | F27: 1 | G27: 1251600 | H27: =G27*F27 -> 1251600 | L27: OK | M27: TF 388 | N27: 45784
